Workbook

Sheet Resumo
A1: SAMPA 135 - Viabilidade e break-even do studio para Airbnb
A2: Valores nominais em R$. Todos os números vêm das abas Premissas e Fluxo mensal; mude as premissas e tudo recalcula.
A5: Unidade
A6: Final | B6: =Premissas!$C$6 -> 6, 7 e 8
A7: Área privativa (m²) | B7: =Premissas!$C$7 -> 21.94
A8: Preço de tabela | B8: =Premissas!$C$14 -> 469760
A9: Preço por m² | B9: =Premissas!$C$15 -> 21411.121
A11: Até as chaves (jan/27 a ago/28)
A12: Pago à incorporadora até as chaves (corrigido INCC) | B12: =SUMIFS('Fluxo mensal'!$F$5:$F$388,'Fluxo mensal'!$A$5:$A$388,"<="&Premissas!$C$25) -> 143618.22
A13: ITBI + registro | B13: =SUM('Fluxo mensal'!$G$5:$G$388) -> 20821.079
A14: Mobília | B14: =SUM('Fluxo mensal'!$H$5:$H$388) -> 30000
A15: Saldo financiado nas chaves (corrigido INCC) | B15: =INDEX('Fluxo mensal'!$N$5:$N$388,MATCH(Premissas!$C$25,'Fluxo mensal'!$A$5:$A$388,0)) -> 369641.09
A17: Operação
A18: Início do aluguel | B18: =Premissas!$C$27 -> 47058
A19: 1ª parcela do financiamento | B19: =INDEX('Fluxo mensal'!$M$5:$M$388,MATCH(1,'Fluxo mensal'!$I$5:$I$388,0)) -> 6609.3568
A20: Resultado mensal do imóvel após IR (1º mês pós ramp-up) | B20: =INDEX('Fluxo mensal'!$W$5:$W$388,MATCH(EDATE(Premissas!$C$27,Premissas!$C$41),'Fluxo mensal'!$A$5:$A$388,0)) -> 1075.6372
A21: Fluxo de caixa médio no 1º ano de aluguel (mês) | B21: =AVERAGEIFS('Fluxo mensal'!$X$5:$X$388,'Fluxo mensal'!$A$5:$A$388,">="&Premissas!$C$27,'Fluxo mensal'!$A$5:$A$388,"<"&EDATE(Premissas!$C$27,12)) -> -5676.6946
A22: Aporte máximo acumulado (pior momento do caixa) | B22: =MIN('Fluxo mensal'!$Y$5:$Y$388) -> -743077.85
A23: Mês do aporte máximo | B23: =INDEX('Fluxo mensal'!$A$5:$A$388,MATCH(MIN('Fluxo mensal'!$Y$5:$Y$388),'Fluxo mensal'!$Y$5:$Y$388,0)) -> 50618
A25: Break-even
A26: 1) Operacional: aluguel líquido cobre a parcela | B26: =IF(MIN('Fluxo mensal'!$AC$5:$AC$388)=0,"Não atinge até dez/58",MIN('Fluxo mensal'!$AC$5:$AC$388)) -> 50649
A27: 2) Caixa: dinheiro investido volta (caixa acumulado ≥ 0) | B27: =IF(MIN('Fluxo mensal'!$AD$5:$AD$388)=0,"Não atinge até dez/58",MIN('Fluxo mensal'!$AD$5:$AD$388)) -> Não atinge até dez/58
A28: 3) Patrimonial: vender devolve tudo (caixa + patrimônio ≥ 0) | B28: =IF(MIN('Fluxo mensal'!$AE$5:$AE$388)=0,"Não atinge até dez/58",MIN('Fluxo mensal'!$AE$5:$AE$388)) -> 50557
A29: Fim do financiamento | B29: =EDATE(Premissas!$C$25,Premissas!$C$32) -> 50618
A31: Fotografias
A32: Posição se vender 5 anos após as chaves | B32: =INDEX('Fluxo mensal'!$AB$5:$AB$388,MATCH(EDATE(Premissas!$C$25,60),'Fluxo mensal'!$A$5:$A$388,0)) -> -126579.54
A33: Posição se vender 10 anos após as chaves | B33: =INDEX('Fluxo mensal'!$AB$5:$AB$388,MATCH(EDATE(Premissas!$C$25,120),'Fluxo mensal'!$A$5:$A$388,0)) -> 10506.773
A34: Posição se vender 20 anos após as chaves | B34: =INDEX('Fluxo mensal'!$AB$5:$AB$388,MATCH(EDATE(Premissas!$C$25,240),'Fluxo mensal'!$A$5:$A$388,0)) -> 663148.59
A36: Como ler:
A37: • Posição total = caixa acumulado (tudo que entrou menos tudo que saiu) + quanto sobraria vendendo o imóvel (após corretagem, saldo devedor e IR sobre o ganho).
A38: • Break-even patrimonial é o indicador do objetivo de alavancagem de patrimônio: a partir daí, vender devolve todo o dinheiro colocado.
A39: • Não inclui custo de oportunidade do dinheiro (ex.: o que o capital renderia no CDI).
A40: • Premissas não informadas pelo usuário (INCC, indexador pós-chaves, diária, ocupação, condomínio, mobília, valorização) estão na aba Premissas com a origem de cada número.

Sheet Premissas
A1: Premissas do estudo - SAMPA 135 (studio para Airbnb)
A2: Edite só as células em azul (amarelo = premissas que mais mexem no resultado). Todo o resto é calculado.
A5: 1. Unidade (da tabela da incorporadora)
A6: Final escolhido (lista) | C6: 6, 7 e 8 | D6: Escolha na lista. Padrão: 21,94 m², a mais próxima do foco de ~20 m².
A7: Área privativa (m²) | C7: =INDEX('Tabela SAMPA 135'!$C$5:$C$14,MATCH(Premissas!$C$6,'Tabela SAMPA 135'!$A$5:$A$14,0)) -> 21.94
A8: Entrada (ato) | C8: =INDEX('Tabela SAMPA 135'!$E$5:$E$14,MATCH(Premissas!$C$6,'Tabela SAMPA 135'!$A$5:$A$14,0)) -> 18790
A9: Parcela 30 e 60 dias (cada uma) | C9: =INDEX('Tabela SAMPA 135'!$F$5:$F$14,MATCH(Premissas!$C$6,'Tabela SAMPA 135'!$A$5:$A$14,0)) -> 18790 | D9: 2 parcelas desse valor (a soma fecha com o preço total)
A10: Parcela mensal (19x) | C10: =INDEX('Tabela SAMPA 135'!$G$5:$G$14,MATCH(Premissas!$C$6,'Tabela SAMPA 135'!$A$5:$A$14,0)) -> 1530
A11: Parcela semestral (3x) | C11: =INDEX('Tabela SAMPA 135'!$H$5:$H$14,MATCH(Premissas!$C$6,'Tabela SAMPA 135'!$A$5:$A$14,0)) -> 9080
A12: Parcela das chaves (ago/28) | C12: =INDEX('Tabela SAMPA 135'!$I$5:$I$14,MATCH(Premissas!$C$6,'Tabela SAMPA 135'!$A$5:$A$14,0)) -> 23490
A13: Saldo financiado na entrega (tabela) | C13: =INDEX('Tabela SAMPA 135'!$J$5:$J$14,MATCH(Premissas!$C$6,'Tabela SAMPA 135'!$A$5:$A$14,0)) -> 333590
A14: Preço total (tabela) | C14: =INDEX('Tabela SAMPA 135'!$K$5:$K$14,MATCH(Premissas!$C$6,'Tabela SAMPA 135'!$A$5:$A$14,0)) -> 469760
A15: Preço por m² | C15: =Premissas!$C$14/Premissas!$C$7 -> 21411.121
A17: 2. Datas
A18: Data-base da tabela | C18: 46266 | D18: Valores da tabela são de set/2026 e corrigem pelo INCC até o pagamento
A19: Data da compra (assinatura) | C19: 46388 | D19: Informado pelo usuário: jan/27
A20: 1ª parcela mensal | C20: 46388 | D20: Tabela: 19 mensais a partir de jan/27
A21: Nº de parcelas mensais | C21: 19
A22: 1ª semestral | C22: 46539 | D22: Tabela: 3 semestrais a partir de jun/27
A23: 2ª semestral | C23: 46722
A24: 3ª semestral | C24: 46905
A25: Entrega das chaves | C25: 46966 | D25: Informado pelo usuário: ago/28
A26: Meses para mobiliar (sem aluguel) | C26: 2 | D26: Informado pelo usuário: 2 meses
A27: Início do aluguel (Airbnb) | C27: =DATE(YEAR(Premissas!$C$25),MONTH(Premissas!$C$25)+Premissas!$C$26+1,1) -> 47058
A29: 3. Correções e financiamento
A30: INCC durante a obra (a.a.) | C30: 0.055 | D30: Estimativa (INCC-FGV recente ~5-6% a.a.). Tabela: corrige mensalmente pelo INCC
A31: Juros do financiamento (a.a.) | C31: 0.12 | D31: Derivado da tabela: parcelas 1 e 120 batem com SAC a 12% a.a.
A32: Prazo do financiamento (meses) | C32: 120 | D32: Tabela: financiamento direto em 120x. Para simular banco, use 360 e a taxa do banco
A33: Correção do saldo pós-chaves (a.a.) | C33: 0.04 | D33: Premissa: IPCA ~4%. A tabela não informa o indexador; confirmar com a incorporadora
A34: ITBI + escritura/registro (% do preço) | C34: 0.04 | D34: ITBI SP 3% + registro ~1%. Pago nas chaves (tabela, nota D)
A35: Mobília, decoração e enxoval | C35: 30000 | D35: Estimativa para ~22 m². Dividido pelos meses de mobília
A37: 4. Operação Airbnb (valores de hoje, corrigidos pela inflação)
A38: Diária média | C38: 230 | D38: Cenário base do estudo (R$ 220-245 média SP). Ajuste conforme a região do prédio
A39: Ocupação média | C39: 0.62 | D39: Mediana de SP: 61-63%
A40: Dias por mês | C40: 30
A41: Meses de ramp-up (início) | C41: 3 | D41: Anúncio novo leva alguns meses para ganhar avaliações
A42: Ocupação no ramp-up (% da média) | C42: 0.6
A43: Taxa Airbnb (anfitrião) | C43: 0.16 | D43: Modelo de taxa única do anfitrião
A44: Gestora (% da receita bruta) | C44: 0.2 | D44: Mercado: 15-28%
A45: Condomínio + IPTU (mês) | C45: 750 | D45: Estimativa. Pago a partir das chaves
...

Sheet Tabela SAMPA 135
A1: SAMPA 135 - Tabela especial de pré-lançamento (set/2026)
A2: Setor Residencial R - 3º ao 15º pavimento. Valores em R$. Entrega estimada: ago/2028.
A4: Final | B4: Vagas | C4: Área privativa (m²) | D4: Tipo | E4: Entrada | F4: Mensais 30/60 dias | G4: 19 mensais (a partir de jan/27) | H4: 3 semestrais (a partir de jun/27) | I4: 1 mensal (ago/28) | J4: Financiamento direto total (ago/28) | K4: Preço total | L4: Fin. direto parcela 1 de 120 | M4: Fin. direto parcela 120 de 120 | N4: Marca vermelha na tabela original
A5: 1 | B5: 0 | C5: 31.77 | D5: XXIV | E5: 26150 | F5: 26150 | G5: 2130 | H5: 12640 | I5: 32680 | J5: 464100 | K5: 653620 | L5: 8271.25 | M5: 3904.2
A6: 2 | B6: 0 | C6: 27.14 | D6: XXV | E6: 22340 | F6: 22340 | G6: 1820 | H6: 10800 | I6: 27920 | J6: 396470 | K6: 558390 | L6: 7065.94 | M6: 3335.27
A7: 3 | B7: 0 | C7: 27.1 | D7: XXVI | E7: 22300 | F7: 22300 | G7: 1820 | H7: 10780 | I7: 27880 | J7: 395880 | K7: 557580 | L7: 7055.42 | M7: 3330.3
A8: 4 | B8: 0 | C8: 27.56 | D8: XXVII | E8: 22680 | F8: 22680 | G8: 1850 | H8: 10960 | I8: 28350 | J8: 402600 | K8: 567020 | L8: 7175.19 | M8: 3386.83
A9: 5 | B9: 0 | C9: 22.34 | D9: XXVIII | E9: 19140 | F9: 19140 | G9: 1560 | H9: 9250 | I9: 23920 | J9: 339670 | K9: 478400 | L9: 6053.64 | M9: 2857.44 | N9: Sim
A10: 6, 7 e 8 | B10: 0 | C10: 21.94 | D10: XXIX | E10: 18790 | F10: 18790 | G10: 1530 | H10: 9080 | I10: 23490 | J10: 333590 | K10: 469760 | L10: 5945.28 | M10: 2806.29 | N10: Sim
A11: 9 | B11: 0 | C11: 22.09 | D11: XXX | E11: 18920 | F11: 18920 | G11: 1540 | H11: 9150 | I11: 23650 | J11: 335870 | K11: 472990 | L11: 5985.92 | M11: 2825.48 | N11: Sim
A12: 10 | B12: 0 | C12: 25.05 | D12: XXXI | E12: 19980 | F12: 19980 | G12: 1630 | H12: 9660 | I12: 24980 | J12: 354730 | K12: 499600 | L12: 6322.04 | M12: 2984.13 | N12: Sim
A13: 11 | B13: 0 | C13: 27.6 | D13: XXXII | E13: 22710 | F13: 22710 | G13: 1850 | H13: 10980 | I13: 28390 | J13: 403190 | K13: 567800 | L13: 7185.7 | M13: 3391.8
A14: 12 | B14: 0 | C14: 28.97 | D14: XXXIII | E14: 23840 | F14: 23840 | G14: 1950 | H14: 11520 | I14: 29800 | J14: 423200 | K14: 596130 | L14: 7542.32 | M14: 3560.13
A16: Notas
A17: A) Valores em reais.
A18: B) Corrigidos mensalmente pelo INCC-FGV até a assinatura do contrato, e demais condições após essa data.
A19: C) Parcelas a partir de ago/2028 incluem juros.
A20: D) Custos de escritura (ITBI, registro) por conta do comprador.
A21: F) A tabela pode ser alterada sem aviso prévio.
A22: G) Previsão de entrega: agosto/2028.
A24: Fonte: tabela de pré-lançamento SAMPA 135 (set/2026) enviada pelo usuário. Valores copiados sem alteração.

Sheet Fluxo mensal
A1: Fluxo mensal - pagamento, operação e break-even (R$ nominais)
A2: Saídas negativas no fluxo de caixa. Pagamentos da obra corrigidos pelo INCC desde a data-base da tabela; financiamento SAC com correção do saldo; receita e custos corrigidos pela inflação.
A4: Mês | B4: Fase | C4: Meses desde a tabela | D4: Pagto incorporadora (tabela) | E4: Fator INCC | F4: Pagto incorporadora corrigido | G4: ITBI + registro | H4: Mobília | I4: Nº parcela financ. | J4: Saldo corrigido | K4: Juros | L4: Amortização | M4: Parcela financiamento | N4: Saldo devedor | O4: Ocupação | P4: Receita bruta | Q4: Taxa Airbnb | R4: Gestora | S4: Condomínio + IPTU | T4: Contas | U4: Manutenção | V4: IR | W4: Resultado do imóvel (após IR) | X4: Fluxo de caixa do mês | Y4: Caixa acumulado | Z4: Valor de mercado | AA4: Patrimônio líquido se vender | AB4: Posição total (caixa + patrimônio) | AC4: Flag: aluguel cobre parcela | AD4: Flag: caixa acumulado ≥ 0 | AE4: Flag: posição ≥ 0
A5: =Premissas!$C$19 -> 46388 | B5: =IF($A5<Premissas!$C$25,"Obra",IF($A5=Premissas!$C$25,"Chaves",IF($A5<Premissas!$C$27,"Mobiliando","Airbnb"))) -> Obra | C5: =(YEAR($A5)-YEAR(Premissas!$C$18))*12+MONTH($A5)-MONTH(Premissas!$C$18) -> 4 | D5: =($A5=Premissas!$C$19)*Premissas!$C$8+(($A5=EDATE(Premissas!$C$19,1))+($A5=EDATE(Premissas!$C$19,2)))*Premissas!$C$9+AND($A5>=Premissas!$C$20,$A5<EDATE(Premissas!$C$20,Premissas!$C$21))*Premissas!$C$10+(($A5=Premissas!$C$22)+($A5=Premissas!$C$23)+($A5=Premissas!$C$24))*Premissas!$C$11+($A5=Premissas!$C$25)*Premissas!$C$12 -> 20320 | E5: =(1+Premissas!$C$57)^C5 -> 1.0180071 | F5: =D5*E5 -> 20685.905 | G5: =($A5=Premissas!$C$25)*Premissas!$C$34*Premissas!$C$14*(1+Premissas!$C$57)^C5 -> 0 | H5: =IF(AND($A5>Premissas!$C$25,$A5<Premissas!$C$27),Premissas!$C$35/MAX(1,Premissas!$C$26),0) -> 0 | I5: =IF(AND($A5>Premissas!$C$25,((YEAR($A5)-YEAR(Premissas!$C$25))*12+MONTH($A5)-MONTH(Premissas!$C$25))<=Premissas!$C$32),((YEAR($A5)-YEAR(Premissas!$C$25))*12+MONTH($A5)-MONTH(Premissas!$C$25)),0) -> 0 | J5: =IF(I5>0,0*(1+Premissas!$C$59),0) -> 0 | K5: =J5*Premissas!$C$58 -> 0 | L5: =IF(I5>0,J5/(Premissas!$C$32-I5+1),0) -> 0 | M5: =K5+L5 -> 0 | N5: =IF($A5=Premissas!$C$25,Premissas!$C$13*E5,IF(I5>0,J5-L5,0)) -> 0 | O5: =IF($A5>=Premissas!$C$27,Premissas!$C$39*IF(((YEAR($A5)-YEAR(Premissas!$C$27))*12+MONTH($A5)-MONTH(Premissas!$C$27))<Premissas!$C$41,Premissas!$C$42,1),0) -> 0 | P5: =O5*Premissas!$C$38*Premissas!$C$40*(1+Premissas!$C$60)^((YEAR($A5)-YEAR(Premissas!$C$19))*12+MONTH($A5)-MONTH(Premissas!$C$19)) -> 0 | Q5: =P5*Premissas!$C$43 -> 0 | R5: =P5*Premissas!$C$44 -> 0 | S5: =IF($A5>=Premissas!$C$25,Premissas!$C$45*(1+Premissas!$C$60)^((YEAR($A5)-YEAR(Premissas!$C$19))*12+MONTH($A5)-MONTH(Premissas!$C$19)),0) -> 0 | T5: =IF($A5>=Premissas!$C$27,Premissas!$C$46*(1+Premissas!$C$60)^((YEAR($A5)-YEAR(Premissas!$C$19))*12+MONTH($A5)-MONTH(Premissas!$C$19)),0) -> 0 | U5: =IF($A5>=Premissas!$C$27,Premissas!$C$47*(1+Premissas!$C$60)^((YEAR($A5)-YEAR(Premissas!$C$19))*12+MONTH($A5)-MONTH(Premissas!$C$19)),0) -> 0 | V5: =IF($A5>=Premissas!$C$27,MAX(0,P5-Q5-R5-S5)*Premissas!$C$49,0) -> 0 | W5: =P5-Q5-R5-S5-T5-U5-V5 -> 0 | X5: =W5-F5-G5-H5-M5 -> -20685.905 | Y5: =X5 -> -20685.905 | Z5: =Premissas!$C$14*(1+Premissas!$C$57)^((YEAR(Premissas!$C$19)-YEAR(Premissas!$C$18))*12+MONTH(Premissas!$C$19)-MONTH(Premissas!$C$18))*(1+Premissas!$C$61)^((YEAR($A5)-YEAR(Premissas!$C$19))*12+MONTH($A5)-MONTH(Premissas!$C$19)) -> 478219.03 | AA5: =IF($A5>=Premissas!$C$25,Z5*(1-Premissas!$C$53)-N5-Premissas!$C$54*MAX(0,Z5*(1-Premissas!$C$53)-(Premissas!$C$14*(1+Premissas!$C$57)^((YEAR(Premissas!$C$25)-YEAR(Premissas!$C$18))*12+MONTH(Premissas!$C$25)-MONTH(Premissas!$C$18))*(1+Premissas!$C$34))),"") | AB5: =IF($A5>=Premissas!$C$25,Y5+AA5,"") | AC5: =IF(AND($A5>=Premissas!$C$27,W5>=M5),$A5,"") | AD5: =IF(AND($A5>=Premissas!$C$27,Y5>=0),$A5,"") | AE5: =IF(AND($A5>=Premissas!$C$25,N(AB5)>=0),$A5,"")
A6: =DATE(YEAR(A5),MONTH(A5)+1,1) -> 46419 | B6: =IF($A6<Premissas!$C$25,"Obra",IF($A6=Premissas!$C$25,"Chaves",IF($A6<Premissas!$C$27,"Mobiliando","Airbnb"))) -> Obra | C6: =(YEAR($A6)-YEAR(Premissas!$C$18))*12+MONTH($A6)-MONTH(Premissas!$C$18) -> 5 | D6: =($A6=Premissas!$C$19)*Premissas!$C$8+(($A6=EDATE(Premissas!$C$19,1))+($A6=EDATE(Premissas!$C$19,2)))*Premissas!$C$9+AND($A6>=Premissas!$C$20,$A6<EDATE(Premissas!$C$20,Premissas!$C$21))*Premissas!$C$10+(($A6=Premissas!$C$22)+($A6=Premissas!$C$23)+($A6=Premissas!$C$24))*Premissas!$C$11+($A6=Premissas!$C$25)*Premissas!$C$12 -> 20320 | E6: =(1+Premissas!$C$57)^C6 -> 1.0225594 | F6: =D6*E6 -> 20778.406 | G6: =($A6=Premissas!$C$25)*Premissas!$C$34*Premissas!$C$14*(1+Premissas!$C$57)^C6 -> 0 | H6: =IF(AND($A6>Premissas!$C$25,$A6<Premissas!$C$27),Premissas!$C$35/MAX(1,Premissas!$C$26),0) -> 0 | I6: =IF(AND($A6>Premissas!$C$25,((YEAR($A6)-YEAR(Premissas!$C$25))*12+MONTH($A6)-MONTH(Premissas!$C$25))<=Premissas!$C$32),((YEAR($A6)-YEAR(Premissas!$C$25))*12+MONTH($A6)-MONTH(Premissas!$C$25)),0) -> 0 | J6: =IF(I6>0,N5*(1+Premissas!$C$59),0) -> 0 | K6: =J6*Premissas!$C$58 -> 0 | L6: =IF(I6>0,J6/(Premissas!$C$32-I6+1),0) -> 0 | M6: =K6+L6 -> 0 | N6: =IF($A6=Premissas!$C$25,Premissas!$C$13*E6,IF(I6>0,J6-L6,0)) -> 0 | O6: =IF($A6>=Premissas!$C$27,Premissas!$C$39*IF(((YEAR($A6)-YEAR(Premissas!$C$27))*12+MONTH($A6)-MONTH(Premissas!$C$27))<Premissas!$C$41,Premissas!$C$42,1),0) -> 0 | P6: =O6*Premissas!$C$38*Premissas!$C$40*(1+Premissas!$C$60)^((YEAR($A6)-YEAR(Premissas!$C$19))*12+MONTH($A6)-MONTH(Premissas!$C$19)) -> 0 | Q6: =P6*Premissas!$C$43 -> 0 | R6: =P6*Premissas!$C$44 -> 0 | S6: =IF($A6>=Premissas!$C$25,Premissas!$C$45*(1+Premissas!$C$60)^((YEAR($A6)-YEAR(Premissas!$C$19))*12+MONTH($A6)-MONTH(Premissas!$C$19)),0) -> 0 | T6: =IF($A6>=Premissas!$C$27,Premissas!$C$46*(1+Premissas!$C$60)^((YEAR($A6)-YEAR(Premissas!$C$19))*12+MONTH($A6)-MONTH(Premissas!$C$19)),0) -> 0 | U6: =IF($A6>=Premissas!$C$27,Premissas!$C$47*(1+Premissas!$C$60)^((YEAR($A6)-YEAR(Premissas!$C$19))*12+MONTH($A6)-MONTH(Premissas!$C$19)),0) -> 0 | V6: =IF($A6>=Premissas!$C$27,MAX(0,P6-Q6-R6-S6)*Premissas!$C$49,0) -> 0 | W6: =P6-Q6-R6-S6-T6-U6-V6 -> 0 | X6: =W6-F6-G6-H6-M6 -> -20778.406 | Y6: =Y5+X6 -> -41464.311 | Z6: =Premissas!$C$14*(1+Premissas!$C$57)^((YEAR(Premissas!$C$19)-YEAR(Premissas!$C$18))*12+MONTH(Premissas!$C$19)-MONTH(Premissas!$C$18))*(1+Premissas!$C$61)^((YEAR($A6)-YEAR(Premissas!$C$19))*12+MONTH($A6)-MONTH(Premissas!$C$19)) -> 480167.35 | AA6: =IF($A6>=Premissas!$C$25,Z6*(1-Premissas!$C$53)-N6-Premissas!$C$54*MAX(0,Z6*(1-Premissas!$C$53)-(Premissas!$C$14*(1+Premissas!$C$57)^((YEAR(Premissas!$C$25)-YEAR(Premissas!$C$18))*12+MONTH(Premissas!$C$25)-MONTH(Premissas!$C$18))*(1+Premissas!$C$34))),"") | AB6: =IF($A6>=Premissas!$C$25,Y6+AA6,"") | AC6: =IF(AND($A6>=Premissas!$C$27,W6>=M6),$A6,"") | AD6: =IF(AND($A6>=Premissas!$C$27,Y6>=0),$A6,"") | AE6: =IF(AND($A6>=Premissas!$C$25,N(AB6)>=0),$A6,"")
A7: =DATE(YEAR(A6),MONTH(A6)+1,1) -> 46447 | B7: =IF($A7<Premissas!$C$25,"Obra",IF($A7=Premissas!$C$25,"Chaves",IF($A7<Premissas!$C$27,"Mobiliando","Airbnb"))) -> Obra | C7: =(YEAR($A7)-YEAR(Premissas!$C$18))*12+MONTH($A7)-MONTH(Premissas!$C$18) -> 6 | D7: =($A7=Premissas!$C$19)*Premissas!$C$8+(($A7=EDATE(Premissas!$C$19,1))+($A7=EDATE(Premissas!$C$19,2)))*Premissas!$C$9+AND($A7>=Premissas!$C$20,$A7<EDATE(Premissas!$C$20,Premissas!$C$21))*Premissas!$C$10+(($A7=Premissas!$C$22)+($A7=Premissas!$C$23)+($A7=Premissas!$C$24))*Premissas!$C$11+($A7=Premissas!$C$25)*Premissas!$C$12 -> 20320 | E7: =(1+Premissas!$C$57)^C7 -> 1.0271319 | F7: =D7*E7 -> 20871.321 | G7: =($A7=Premissas!$C$25)*Premissas!$C$34*Premissas!$C$14*(1+Premissas!$C$57)^C7 -> 0 | H7: =IF(AND($A7>Premissas!$C$25,$A7<Premissas!$C$27),Premissas!$C$35/MAX(1,Premissas!$C$26),0) -> 0 | I7: =IF(AND($A7>Premissas!$C$25,((YEAR($A7)-YEAR(Premissas!$C$25))*12+MONTH($A7)-MONTH(Premissas!$C$25))<=Premissas!$C$32),((YEAR($A7)-YEAR(Premissas!$C$25))*12+MONTH($A7)-MONTH(Premissas!$C$25)),0) -> 0 | J7: =IF(I7>0,N6*(1+Premissas!$C$59),0) -> 0 | K7: =J7*Premissas!$C$58 -> 0 | L7: =IF(I7>0,J7/(Premissas!$C$32-I7+1),0) -> 0 | M7: =K7+L7 -> 0 | N7: =IF($A7=Premissas!$C$25,Premissas!$C$13*E7,IF(I7>0,J7-L7,0)) -> 0 | O7: =IF($A7>=Premissas!$C$27,Premissas!$C$39*IF(((YEAR($A7)-YEAR(Premissas!$C$27))*12+MONTH($A7)-MONTH(Premissas!$C$27))<Premissas!$C$41,Premissas!$C$42,1),0) -> 0 | P7: =O7*Premissas!$C$38*Premissas!$C$40*(1+Premissas!$C$60)^((YEAR($A7)-YEAR(Premissas!$C$19))*12+MONTH($A7)-MONTH(Premissas!$C$19)) -> 0 | Q7: =P7*Premissas!$C$43 -> 0 | R7: =P7*Premissas!$C$44 -> 0 | S7: =IF($A7>=Premissas!$C$25,Premissas!$C$45*(1+Premissas!$C$60)^((YEAR($A7)-YEAR(Premissas!$C$19))*12+MONTH($A7)-MONTH(Premissas!$C$19)),0) -> 0 | T7: =IF($A7>=Premissas!$C$27,Premissas!$C$46*(1+Premissas!$C$60)^((YEAR($A7)-YEAR(Premissas!$C$19))*12+MONTH($A7)-MONTH(Premissas!$C$19)),0) -> 0 | U7: =IF($A7>=Premissas!$C$27,Premissas!$C$47*(1+Premissas!$C$60)^((YEAR($A7)-YEAR(Premissas!$C$19))*12+MONTH($A7)-MONTH(Premissas!$C$19)),0) -> 0 | V7: =IF($A7>=Premissas!$C$27,MAX(0,P7-Q7-R7-S7)*Premissas!$C$49,0) -> 0 | W7: =P7-Q7-R7-S7-T7-U7-V7 -> 0 | X7: =W7-F7-G7-H7-M7 -> -20871.321 | Y7: =Y6+X7 -> -62335.632 | Z7: =Premissas!$C$14*(1+Premissas!$C$57)^((YEAR(Premissas!$C$19)-YEAR(Premissas!$C$18))*12+MONTH(Premissas!$C$19)-MONTH(Premissas!$C$18))*(1+Premissas!$C$61)^((YEAR($A7)-YEAR(Premissas!$C$19))*12+MONTH($A7)-MONTH(Premissas!$C$19)) -> 482123.61 | AA7: =IF($A7>=Premissas!$C$25,Z7*(1-Premissas!$C$53)-N7-Premissas!$C$54*MAX(0,Z7*(1-Premissas!$C$53)-(Premissas!$C$14*(1+Premissas!$C$57)^((YEAR(Premissas!$C$25)-YEAR(Premissas!$C$18))*12+MONTH(Premissas!$C$25)-MONTH(Premissas!$C$18))*(1+Premissas!$C$34))),"") | AB7: =IF($A7>=Premissas!$C$25,Y7+AA7,"") | AC7: =IF(AND($A7>=Premissas!$C$27,W7>=M7),$A7,"") | AD7: =IF(AND($A7>=Premissas!$C$27,Y7>=0),$A7,"") | AE7: =IF(AND($A7>=Premissas!$C$25,N(AB7)>=0),$A7,"")
A8: =DATE(YEAR(A7),MONTH(A7)+1,1) -> 46478 | B8: =IF($A8<Premissas!$C$25,"Obra",IF($A8=Premissas!$C$25,"Chaves",IF($A8<Premissas!$C$27,"Mobiliando","Airbnb"))) -> Obra | C8: =(YEAR($A8)-YEAR(Premissas!$C$18))*12+MONTH($A8)-MONTH(Premissas!$C$18) -> 7 | D8: =($A8=Premissas!$C$19)*Premissas!$C$8+(($A8=EDATE(Premissas!$C$19,1))+($A8=EDATE(Premissas!$C$19,2)))*Premissas!$C$9+AND($A8>=Premissas!$C$20,$A8<EDATE(Premissas!$C$20,Premissas!$C$21))*Premissas!$C$10+(($A8=Premissas!$C$22)+($A8=Premissas!$C$23)+($A8=Premissas!$C$24))*Premissas!$C$11+($A8=Premissas!$C$25)*Premissas!$C$12 -> 1530 | E8: =(1+Premissas!$C$57)^C8 -> 1.031725 | F8: =D8*E8 -> 1578.5392 | G8: =($A8=Premissas!$C$25)*Premissas!$C$34*Premissas!$C$14*(1+Premissas!$C$57)^C8 -> 0 | H8: =IF(AND($A8>Premissas!$C$25,$A8<Premissas!$C$27),Premissas!$C$35/MAX(1,Premissas!$C$26),0) -> 0 | I8: =IF(AND($A8>Premissas!$C$25,((YEAR($A8)-YEAR(Premissas!$C$25))*12+MONTH($A8)-MONTH(Premissas!$C$25))<=Premissas!$C$32),((YEAR($A8)-YEAR(Premissas!$C$25))*12+MONTH($A8)-MONTH(Premissas!$C$25)),0) -> 0 | J8: =IF(I8>0,N7*(1+Premissas!$C$59),0) -> 0 | K8: =J8*Premissas!$C$58 -> 0 | L8: =IF(I8>0,J8/(Premissas!$C$32-I8+1),0) -> 0 | M8: =K8+L8 -> 0 | N8: =IF($A8=Premissas!$C$25,Premissas!$C$13*E8,IF(I8>0,J8-L8,0)) -> 0 | O8: =IF($A8>=Premissas!$C$27,Premissas!$C$39*IF(((YEAR($A8)-YEAR(Premissas!$C$27))*12+MONTH($A8)-MONTH(Premissas!$C$27))<Premissas!$C$41,Premissas!$C$42,1),0) -> 0 | P8: =O8*Premissas!$C$38*Premissas!$C$40*(1+Premissas!$C$60)^((YEAR($A8)-YEAR(Premissas!$C$19))*12+MONTH($A8)-MONTH(Premissas!$C$19)) -> 0 | Q8: =P8*Premissas!$C$43 -> 0 | R8: =P8*Premissas!$C$44 -> 0 | S8: =IF($A8>=Premissas!$C$25,Premissas!$C$45*(1+Premissas!$C$60)^((YEAR($A8)-YEAR(Premissas!$C$19))*12+MONTH($A8)-MONTH(Premissas!$C$19)),0) -> 0 | T8: =IF($A8>=Premissas!$C$27,Premissas!$C$46*(1+Premissas!$C$60)^((YEAR($A8)-YEAR(Premissas!$C$19))*12+MONTH($A8)-MONTH(Premissas!$C$19)),0) -> 0 | U8: =IF($A8>=Premissas!$C$27,Premissas!$C$47*(1+Premissas!$C$60)^((YEAR($A8)-YEAR(Premissas!$C$19))*12+MONTH($A8)-MONTH(Premissas!$C$19)),0) -> 0 | V8: =IF($A8>=Premissas!$C$27,MAX(0,P8-Q8-R8-S8)*Premissas!$C$49,0) -> 0 | W8: =P8-Q8-R8-S8-T8-U8-V8 -> 0 | X8: =W8-F8-G8-H8-M8 -> -1578.5392 | Y8: =Y7+X8 -> -63914.171 | Z8: =Premissas!$C$14*(1+Premissas!$C$57)^((YEAR(Premissas!$C$19)-YEAR(Premissas!$C$18))*12+MONTH(Premissas!$C$19)-MONTH(Premissas!$C$18))*(1+Premissas!$C$61)^((YEAR($A8)-YEAR(Premissas!$C$19))*12+MONTH($A8)-MONTH(Premissas!$C$19)) -> 484087.85 | AA8: =IF($A8>=Premissas!$C$25,Z8*(1-Premissas!$C$53)-N8-Premissas!$C$54*MAX(0,Z8*(1-Premissas!$C$53)-(Premissas!$C$14*(1+Premissas!$C$57)^((YEAR(Premissas!$C$25)-YEAR(Premissas!$C$18))*12+MONTH(Premissas!$C$25)-MONTH(Premissas!$C$18))*(1+Premissas!$C$34))),"") | AB8: =IF($A8>=Premissas!$C$25,Y8+AA8,"") | AC8: =IF(AND($A8>=Premissas!$C$27,W8>=M8),$A8,"") | AD8: =IF(AND($A8>=Premissas!$C$27,Y8>=0),$A8,"") | AE8: =IF(AND($A8>=Premissas!$C$25,N(AB8)>=0),$A8,"")
A9: =DATE(YEAR(A8),MONTH(A8)+1,1) -> 46508 | B9: =IF($A9<Premissas!$C$25,"Obra",IF($A9=Premissas!$C$25,"Chaves",IF($A9<Premissas!$C$27,"Mobiliando","Airbnb"))) -> Obra | C9: =(YEAR($A9)-YEAR(Premissas!$C$18))*12+MONTH($A9)-MONTH(Premissas!$C$18) -> 8 | D9: =($A9=Premissas!$C$19)*Premissas!$C$8+(($A9=EDATE(Premissas!$C$19,1))+($A9=EDATE(Premissas!$C$19,2)))*Premissas!$C$9+AND($A9>=Premissas!$C$20,$A9<EDATE(Premissas!$C$20,Premissas!$C$21))*Premissas!$C$10+(($A9=Premissas!$C$22)+($A9=Premissas!$C$23)+($A9=Premissas!$C$24))*Premissas!$C$11+($A9=Premissas!$C$25)*Premissas!$C$12 -> 1530 | E9: =(1+Premissas!$C$57)^C9 -> 1.0363385 | F9: =D9*E9 -> 1585.5979 | G9: =($A9=Premissas!$C$25)*Premissas!$C$34*Premissas!$C$14*(1+Premissas!$C$57)^C9 -> 0 | H9: =IF(AND($A9>Premissas!$C$25,$A9<Premissas!$C$27),Premissas!$C$35/MAX(1,Premissas!$C$26),0) -> 0 | I9: =IF(AND($A9>Premissas!$C$25,((YEAR($A9)-YEAR(Premissas!$C$25))*12+MONTH($A9)-MONTH(Premissas!$C$25))<=Premissas!$C$32),((YEAR($A9)-YEAR(Premissas!$C$25))*12+MONTH($A9)-MONTH(Premissas!$C$25)),0) -> 0 | J9: =IF(I9>0,N8*(1+Premissas!$C$59),0) -> 0 | K9: =J9*Premissas!$C$58 -> 0 | L9: =IF(I9>0,J9/(Premissas!$C$32-I9+1),0) -> 0 | M9: =K9+L9 -> 0 | N9: =IF($A9=Premissas!$C$25,Premissas!$C$13*E9,IF(I9>0,J9-L9,0)) -> 0 | O9: =IF($A9>=Premissas!$C$27,Premissas!$C$39*IF(((YEAR($A9)-YEAR(Premissas!$C$27))*12+MONTH($A9)-MONTH(Premissas!$C$27))<Premissas!$C$41,Premissas!$C$42,1),0) -> 0 | P9: =O9*Premissas!$C$38*Premissas!$C$40*(1+Premissas!$C$60)^((YEAR($A9)-YEAR(Premissas!$C$19))*12+MONTH($A9)-MONTH(Premissas!$C$19)) -> 0 | Q9: =P9*Premissas!$C$43 -> 0 | R9: =P9*Premissas!$C$44 -> 0 | S9: =IF($A9>=Premissas!$C$25,Premissas!$C$45*(1+Premissas!$C$60)^((YEAR($A9)-YEAR(Premissas!$C$19))*12+MONTH($A9)-MONTH(Premissas!$C$19)),0) -> 0 | T9: =IF($A9>=Premissas!$C$27,Premissas!$C$46*(1+Premissas!$C$60)^((YEAR($A9)-YEAR(Premissas!$C$19))*12+MONTH($A9)-MONTH(Premissas!$C$19)),0) -> 0 | U9: =IF($A9>=Premissas!$C$27,Premissas!$C$47*(1+Premissas!$C$60)^((YEAR($A9)-YEAR(Premissas!$C$19))*12+MONTH($A9)-MONTH(Premissas!$C$19)),0) -> 0 | V9: =IF($A9>=Premissas!$C$27,MAX(0,P9-Q9-R9-S9)*Premissas!$C$49,0) -> 0 | W9: =P9-Q9-R9-S9-T9-U9-V9 -> 0 | X9: =W9-F9-G9-H9-M9 -> -1585.5979 | Y9: =Y8+X9 -> -65499.769 | Z9: =Premissas!$C$14*(1+Premissas!$C$57)^((YEAR(Premissas!$C$19)-YEAR(Premissas!$C$18))*12+MONTH(Premissas!$C$19)-MONTH(Premissas!$C$18))*(1+Premissas!$C$61)^((YEAR($A9)-YEAR(Premissas!$C$19))*12+MONTH($A9)-MONTH(Premissas!$C$19)) -> 486060.08 | AA9: =IF($A9>=Premissas!$C$25,Z9*(1-Premissas!$C$53)-N9-Premissas!$C$54*MAX(0,Z9*(1-Premissas!$C$53)-(Premissas!$C$14*(1+Premissas!$C$57)^((YEAR(Premissas!$C$25)-YEAR(Premissas!$C$18))*12+MONTH(Premissas!$C$25)-MONTH(Premissas!$C$18))*(1+Premissas!$C$34))),"") | AB9: =IF($A9>=Premissas!$C$25,Y9+AA9,"") | AC9: =IF(AND($A9>=Premissas!$C$27,W9>=M9),$A9,"") | AD9: =IF(AND($A9>=Premissas!$C$27,Y9>=0),$A9,"") | AE9: =IF(AND($A9>=Premissas!$C$25,N(AB9)>=0),$A9,"")
A10: =DATE(YEAR(A9),MONTH(A9)+1,1) -> 46539 | B10: =IF($A10<Premissas!$C$25,"Obra",IF($A10=Premissas!$C$25,"Chaves",IF($A10<Premissas!$C$27,"Mobiliando","Airbnb"))) -> Obra | C10: =(YEAR($A10)-YEAR(Premissas!$C$18))*12+MONTH($A10)-MONTH(Premissas!$C$18) -> 9 | D10: =($A10=Premissas!$C$19)*Premissas!$C$8+(($A10=EDATE(Premissas!$C$19,1))+($A10=EDATE(Premissas!$C$19,2)))*Premissas!$C$9+AND($A10>=Premissas!$C$20,$A10<EDATE(Premissas!$C$20,Premissas!$C$21))*Premissas!$C$10+(($A10=Premissas!$C$22)+($A10=Premissas!$C$23)+($A10=Premissas!$C$24))*Premissas!$C$11+($A10=Premissas!$C$25)*Premissas!$C$12 -> 10610 | E10: =(1+Premissas!$C$57)^C10 -> 1.0409727 | F10: =D10*E10 -> 11044.72 | G10: =($A10=Premissas!$C$25)*Premissas!$C$34*Premissas!$C$14*(1+Premissas!$C$57)^C10 -> 0 | H10: =IF(AND($A10>Premissas!$C$25,$A10<Premissas!$C$27),Premissas!$C$35/MAX(1,Premissas!$C$26),0) -> 0 | I10: =IF(AND($A10>Premissas!$C$25,((YEAR($A10)-YEAR(Premissas!$C$25))*12+MONTH($A10)-MONTH(Premissas!$C$25))<=Premissas!$C$32),((YEAR($A10)-YEAR(Premissas!$C$25))*12+MONTH($A10)-MONTH(Premissas!$C$25)),0) -> 0 | J10: =IF(I10>0,N9*(1+Premissas!$C$59),0) -> 0 | K10: =J10*Premissas!$C$58 -> 0 | L10: =IF(I10>0,J10/(Premissas!$C$32-I10+1),0) -> 0 | M10: =K10+L10 -> 0 | N10: =IF($A10=Premissas!$C$25,Premissas!$C$13*E10,IF(I10>0,J10-L10,0)) -> 0 | O10: =IF($A10>=Premissas!$C$27,Premissas!$C$39*IF(((YEAR($A10)-YEAR(Premissas!$C$27))*12+MONTH($A10)-MONTH(Premissas!$C$27))<Premissas!$C$41,Premissas!$C$42,1),0) -> 0 | P10: =O10*Premissas!$C$38*Premissas!$C$40*(1+Premissas!$C$60)^((YEAR($A10)-YEAR(Premissas!$C$19))*12+MONTH($A10)-MONTH(Premissas!$C$19)) -> 0 | Q10: =P10*Premissas!$C$43 -> 0 | R10: =P10*Premissas!$C$44 -> 0 | S10: =IF($A10>=Premissas!$C$25,Premissas!$C$45*(1+Premissas!$C$60)^((YEAR($A10)-YEAR(Premissas!$C$19))*12+MONTH($A10)-MONTH(Premissas!$C$19)),0) -> 0 | T10: =IF($A10>=Premissas!$C$27,Premissas!$C$46*(1+Premissas!$C$60)^((YEAR($A10)-YEAR(Premissas!$C$19))*12+MONTH($A10)-MONTH(Premissas!$C$19)),0) -> 0 | U10: =IF($A10>=Premissas!$C$27,Premissas!$C$47*(1+Premissas!$C$60)^((YEAR($A10)-YEAR(Premissas!$C$19))*12+MONTH($A10)-MONTH(Premissas!$C$19)),0) -> 0 | V10: =IF($A10>=Premissas!$C$27,MAX(0,P10-Q10-R10-S10)*Premissas!$C$49,0) -> 0 | W10: =P10-Q10-R10-S10-T10-U10-V10 -> 0 | X10: =W10-F10-G10-H10-M10 -> -11044.72 | Y10: =Y9+X10 -> -76544.489 | Z10: =Premissas!$C$14*(1+Premissas!$C$57)^((YEAR(Premissas!$C$19)-YEAR(Premissas!$C$18))*12+MONTH(Premissas!$C$19)-MONTH(Premissas!$C$18))*(1+Premissas!$C$61)^((YEAR($A10)-YEAR(Premissas!$C$19))*12+MONTH($A10)-MONTH(Premissas!$C$19)) -> 488040.35 | AA10: =IF($A10>=Premissas!$C$25,Z10*(1-Premissas!$C$53)-N10-Premissas!$C$54*MAX(0,Z10*(1-Premissas!$C$53)-(Premissas!$C$14*(1+Premissas!$C$57)^((YEAR(Premissas!$C$25)-YEAR(Premissas!$C$18))*12+MONTH(Premissas!$C$25)-MONTH(Premissas!$C$18))*(1+Premissas!$C$34))),"") | AB10: =IF($A10>=Premissas!$C$25,Y10+AA10,"") | AC10: =IF(AND($A10>=Premissas!$C$27,W10>=M10),$A10,"") | AD10: =IF(AND($A10>=Premissas!$C$27,Y10>=0),$A10,"") | AE10: =IF(AND($A10>=Premissas!$C$25,N(AB10)>=0),$A10,"")
A11: =DATE(YEAR(A10),MONTH(A10)+1,1) -> 46569 | B11: =IF($A11<Premissas!$C$25,"Obra",IF($A11=Premissas!$C$25,"Chaves",IF($A11<Premissas!$C$27,"Mobiliando","Airbnb"))) -> Obra | C11: =(YEAR($A11)-YEAR(Premissas!$C$18))*12+MONTH($A11)-MONTH(Premissas!$C$18) -> 10 | D11: =($A11=Premissas!$C$19)*Premissas!$C$8+(($A11=EDATE(Premissas!$C$19,1))+($A11=EDATE(Premissas!$C$19,2)))*Premissas!$C$9+AND($A11>=Premissas!$C$20,$A11<EDATE(Premissas!$C$20,Premissas!$C$21))*Premissas!$C$10+(($A11=Premissas!$C$22)+($A11=Premissas!$C$23)+($A11=Premissas!$C$24))*Premissas!$C$11+($A11=Premissas!$C$25)*Premissas!$C$12 -> 1530 | E11: =(1+Premissas!$C$57)^C11 -> 1.0456276 | F11: =D11*E11 -> 1599.8103 | G11: =($A11=Premissas!$C$25)*Premissas!$C$34*Premissas!$C$14*(1+Premissas!$C$57)^C11 -> 0 | H11: =IF(AND($A11>Premissas!$C$25,$A11<Premissas!$C$27),Premissas!$C$35/MAX(1,Premissas!$C$26),0) -> 0 | I11: =IF(AND($A11>Premissas!$C$25,((YEAR($A11)-YEAR(Premissas!$C$25))*12+MONTH($A11)-MONTH(Premissas!$C$25))<=Premissas!$C$32),((YEAR($A11)-YEAR(Premissas!$C$25))*12+MONTH($A11)-MONTH(Premissas!$C$25)),0) -> 0 | J11: =IF(I11>0,N10*(1+Premissas!$C$59),0) -> 0 | K11: =J11*Premissas!$C$58 -> 0 | L11: =IF(I11>0,J11/(Premissas!$C$32-I11+1),0) -> 0 | M11: =K11+L11 -> 0 | N11: =IF($A11=Premissas!$C$25,Premissas!$C$13*E11,IF(I11>0,J11-L11,0)) -> 0 | O11: =IF($A11>=Premissas!$C$27,Premissas!$C$39*IF(((YEAR($A11)-YEAR(Premissas!$C$27))*12+MONTH($A11)-MONTH(Premissas!$C$27))<Premissas!$C$41,Premissas!$C$42,1),0) -> 0 | P11: =O11*Premissas!$C$38*Premissas!$C$40*(1+Premissas!$C$60)^((YEAR($A11)-YEAR(Premissas!$C$19))*12+MONTH($A11)-MONTH(Premissas!$C$19)) -> 0 | Q11: =P11*Premissas!$C$43 -> 0 | R11: =P11*Premissas!$C$44 -> 0 | S11: =IF($A11>=Premissas!$C$25,Premissas!$C$45*(1+Premissas!$C$60)^((YEAR($A11)-YEAR(Premissas!$C$19))*12+MONTH($A11)-MONTH(Premissas!$C$19)),0) -> 0 | T11: =IF($A11>=Premissas!$C$27,Premissas!$C$46*(1+Premissas!$C$60)^((YEAR($A11)-YEAR(Premissas!$C$19))*12+MONTH($A11)-MONTH(Premissas!$C$19)),0) -> 0 | U11: =IF($A11>=Premissas!$C$27,Premissas!$C$47*(1+Premissas!$C$60)^((YEAR($A11)-YEAR(Premissas!$C$19))*12+MONTH($A11)-MONTH(Premissas!$C$19)),0) -> 0 | V11: =IF($A11>=Premissas!$C$27,MAX(0,P11-Q11-R11-S11)*Premissas!$C$49,0) -> 0 | W11: =P11-Q11-R11-S11-T11-U11-V11 -> 0 | X11: =W11-F11-G11-H11-M11 -> -1599.8103 | Y11: =Y10+X11 -> -78144.3 | Z11: =Premissas!$C$14*(1+Premissas!$C$57)^((YEAR(Premissas!$C$19)-YEAR(Premissas!$C$18))*12+MONTH(Premissas!$C$19)-MONTH(Premissas!$C$18))*(1+Premissas!$C$61)^((YEAR($A11)-YEAR(Premissas!$C$19))*12+MONTH($A11)-MONTH(Premissas!$C$19)) -> 490028.69 | AA11: =IF($A11>=Premissas!$C$25,Z11*(1-Premissas!$C$53)-N11-Premissas!$C$54*MAX(0,Z11*(1-Premissas!$C$53)-(Premissas!$C$14*(1+Premissas!$C$57)^((YEAR(Premissas!$C$25)-YEAR(Premissas!$C$18))*12+MONTH(Premissas!$C$25)-MONTH(Premissas!$C$18))*(1+Premissas!$C$34))),"") | AB11: =IF($A11>=Premissas!$C$25,Y11+AA11,"") | AC11: =IF(AND($A11>=Premissas!$C$27,W11>=M11),$A11,"") | AD11: =IF(AND($A11>=Premissas!$C$27,Y11>=0),$A11,"") | AE11: =IF(AND($A11>=Premissas!$C$25,N(AB11)>=0),$A11,"")
A12: =DATE(YEAR(A11),MONTH(A11)+1,1) -> 46600 | B12: =IF($A12<Premissas!$C$25,"Obra",IF($A12=Premissas!$C$25,"Chaves",IF($A12<Premissas!$C$27,"Mobiliando","Airbnb"))) -> Obra | C12: =(YEAR($A12)-YEAR(Premissas!$C$18))*12+MONTH($A12)-MONTH(Premissas!$C$18) -> 11 | D12: =($A12=Premissas!$C$19)*Premissas!$C$8+(($A12=EDATE(Premissas!$C$19,1))+($A12=EDATE(Premissas!$C$19,2)))*Premissas!$C$9+AND($A12>=Premissas!$C$20,$A12<EDATE(Premissas!$C$20,Premissas!$C$21))*Premissas!$C$10+(($A12=Premissas!$C$22)+($A12=Premissas!$C$23)+($A12=Premissas!$C$24))*Premissas!$C$11+($A12=Premissas!$C$25)*Premissas!$C$12 -> 1530 | E12: =(1+Premissas!$C$57)^C12 -> 1.0503034 | F12: =D12*E12 -> 1606.9641 | G12: =($A12=Premissas!$C$25)*Premissas!$C$34*Premissas!$C$14*(1+Premissas!$C$57)^C12 -> 0 | H12: =IF(AND($A12>Premissas!$C$25,$A12<Premissas!$C$27),Premissas!$C$35/MAX(1,Premissas!$C$26),0) -> 0 | I12: =IF(AND($A12>Premissas!$C$25,((YEAR($A12)-YEAR(Premissas!$C$25))*12+MONTH($A12)-MONTH(Premissas!$C$25))<=Premissas!$C$32),((YEAR($A12)-YEAR(Premissas!$C$25))*12+MONTH($A12)-MONTH(Premissas!$C$25)),0) -> 0 | J12: =IF(I12>0,N11*(1+Premissas!$C$59),0) -> 0 | K12: =J12*Premissas!$C$58 -> 0 | L12: =IF(I12>0,J12/(Premissas!$C$32-I12+1),0) -> 0 | M12: =K12+L12 -> 0 | N12: =IF($A12=Premissas!$C$25,Premissas!$C$13*E12,IF(I12>0,J12-L12,0)) -> 0 | O12: =IF($A12>=Premissas!$C$27,Premissas!$C$39*IF(((YEAR($A12)-YEAR(Premissas!$C$27))*12+MONTH($A12)-MONTH(Premissas!$C$27))<Premissas!$C$41,Premissas!$C$42,1),0) -> 0 | P12: =O12*Premissas!$C$38*Premissas!$C$40*(1+Premissas!$C$60)^((YEAR($A12)-YEAR(Premissas!$C$19))*12+MONTH($A12)-MONTH(Premissas!$C$19)) -> 0 | Q12: =P12*Premissas!$C$43 -> 0 | R12: =P12*Premissas!$C$44 -> 0 | S12: =IF($A12>=Premissas!$C$25,Premissas!$C$45*(1+Premissas!$C$60)^((YEAR($A12)-YEAR(Premissas!$C$19))*12+MONTH($A12)-MONTH(Premissas!$C$19)),0) -> 0 | T12: =IF($A12>=Premissas!$C$27,Premissas!$C$46*(1+Premissas!$C$60)^((YEAR($A12)-YEAR(Premissas!$C$19))*12+MONTH($A12)-MONTH(Premissas!$C$19)),0) -> 0 | U12: =IF($A12>=Premissas!$C$27,Premissas!$C$47*(1+Premissas!$C$60)^((YEAR($A12)-YEAR(Premissas!$C$19))*12+MONTH($A12)-MONTH(Premissas!$C$19)),0) -> 0 | V12: =IF($A12>=Premissas!$C$27,MAX(0,P12-Q12-R12-S12)*Premissas!$C$49,0) -> 0 | W12: =P12-Q12-R12-S12-T12-U12-V12 -> 0 | X12: =W12-F12-G12-H12-M12 -> -1606.9641 | Y12: =Y11+X12 -> -79751.264 | Z12: =Premissas!$C$14*(1+Premissas!$C$57)^((YEAR(Premissas!$C$19)-YEAR(Premissas!$C$18))*12+MONTH(Premissas!$C$19)-MONTH(Premissas!$C$18))*(1+Premissas!$C$61)^((YEAR($A12)-YEAR(Premissas!$C$19))*12+MONTH($A12)-MONTH(Premissas!$C$19)) -> 492025.12 | AA12: =IF($A12>=Premissas!$C$25,Z12*(1-Premissas!$C$53)-N12-Premissas!$C$54*MAX(0,Z12*(1-Premissas!$C$53)-(Premissas!$C$14*(1+Premissas!$C$57)^((YEAR(Premissas!$C$25)-YEAR(Premissas!$C$18))*12+MONTH(Premissas!$C$25)-MONTH(Premissas!$C$18))*(1+Premissas!$C$34))),"") | AB12: =IF($A12>=Premissas!$C$25,Y12+AA12,"") | AC12: =IF(AND($A12>=Premissas!$C$27,W12>=M12),$A12,"") | AD12: =IF(AND($A12>=Premissas!$C$27,Y12>=0),$A12,"") | AE12: =IF(AND($A12>=Premissas!$C$25,N(AB12)>=0),$A12,"")
A13: =DATE(YEAR(A12),MONTH(A12)+1,1) -> 46631 | B13: =IF($A13<Premissas!$C$25,"Obra",IF($A13=Premissas!$C$25,"Chaves",IF($A13<Premissas!$C$27,"Mobiliando","Airbnb"))) -> Obra | C13: =(YEAR($A13)-YEAR(Premissas!$C$18))*12+MONTH($A13)-MONTH(Premissas!$C$18) -> 12 | D13: =($A13=Premissas!$C$19)*Premissas!$C$8+(($A13=EDATE(Premissas!$C$19,1))+($A13=EDATE(Premissas!$C$19,2)))*Premissas!$C$9+AND($A13>=Premissas!$C$20,$A13<EDATE(Premissas!$C$20,Premissas!$C$21))*Premissas!$C$10+(($A13=Premissas!$C$22)+($A13=Premissas!$C$23)+($A13=Premissas!$C$24))*Premissas!$C$11+($A13=Premissas!$C$25)*Premissas!$C$12 -> 1530 | E13: =(1+Premissas!$C$57)^C13 -> 1.055 | F13: =D13*E13 -> 1614.15 | G13: =($A13=Premissas!$C$25)*Premissas!$C$34*Premissas!$C$14*(1+Premissas!$C$57)^C13 -> 0 | H13: =IF(AND($A13>Premissas!$C$25,$A13<Premissas!$C$27),Premissas!$C$35/MAX(1,Premissas!$C$26),0) -> 0 | I13: =IF(AND($A13>Premissas!$C$25,((YEAR($A13)-YEAR(Premissas!$C$25))*12+MONTH($A13)-MONTH(Premissas!$C$25))<=Premissas!$C$32),((YEAR($A13)-YEAR(Premissas!$C$25))*12+MONTH($A13)-MONTH(Premissas!$C$25)),0) -> 0 | J13: =IF(I13>0,N12*(1+Premissas!$C$59),0) -> 0 | K13: =J13*Premissas!$C$58 -> 0 | L13: =IF(I13>0,J13/(Premissas!$C$32-I13+1),0) -> 0 | M13: =K13+L13 -> 0 | N13: =IF($A13=Premissas!$C$25,Premissas!$C$13*E13,IF(I13>0,J13-L13,0)) -> 0 | O13: =IF($A13>=Premissas!$C$27,Premissas!$C$39*IF(((YEAR($A13)-YEAR(Premissas!$C$27))*12+MONTH($A13)-MONTH(Premissas!$C$27))<Premissas!$C$41,Premissas!$C$42,1),0) -> 0 | P13: =O13*Premissas!$C$38*Premissas!$C$40*(1+Premissas!$C$60)^((YEAR($A13)-YEAR(Premissas!$C$19))*12+MONTH($A13)-MONTH(Premissas!$C$19)) -> 0 | Q13: =P13*Premissas!$C$43 -> 0 | R13: =P13*Premissas!$C$44 -> 0 | S13: =IF($A13>=Premissas!$C$25,Premissas!$C$45*(1+Premissas!$C$60)^((YEAR($A13)-YEAR(Premissas!$C$19))*12+MONTH($A13)-MONTH(Premissas!$C$19)),0) -> 0 | T13: =IF($A13>=Premissas!$C$27,Premissas!$C$46*(1+Premissas!$C$60)^((YEAR($A13)-YEAR(Premissas!$C$19))*12+MONTH($A13)-MONTH(Premissas!$C$19)),0) -> 0 | U13: =IF($A13>=Premissas!$C$27,Premissas!$C$47*(1+Premissas!$C$60)^((YEAR($A13)-YEAR(Premissas!$C$19))*12+MONTH($A13)-MONTH(Premissas!$C$19)),0) -> 0 | V13: =IF($A13>=Premissas!$C$27,MAX(0,P13-Q13-R13-S13)*Premissas!$C$49,0) -> 0 | W13: =P13-Q13-R13-S13-T13-U13-V13 -> 0 | X13: =W13-F13-G13-H13-M13 -> -1614.15 | Y13: =Y12+X13 -> -81365.414 | Z13: =Premissas!$C$14*(1+Premissas!$C$57)^((YEAR(Premissas!$C$19)-YEAR(Premissas!$C$18))*12+MONTH(Premissas!$C$19)-MONTH(Premissas!$C$18))*(1+Premissas!$C$61)^((YEAR($A13)-YEAR(Premissas!$C$19))*12+MONTH($A13)-MONTH(Premissas!$C$19)) -> 494029.69 | AA13: =IF($A13>=Premissas!$C$25,Z13*(1-Premissas!$C$53)-N13-Premissas!$C$54*MAX(0,Z13*(1-Premissas!$C$53)-(Premissas!$C$14*(1+Premissas!$C$57)^((YEAR(Premissas!$C$25)-YEAR(Premissas!$C$18))*12+MONTH(Premissas!$C$25)-MONTH(Premissas!$C$18))*(1+Premissas!$C$34))),"") | AB13: =IF($A13>=Premissas!$C$25,Y13+AA13,"") | AC13: =IF(AND($A13>=Premissas!$C$27,W13>=M13),$A13,"") | AD13: =IF(AND($A13>=Premissas!$C$27,Y13>=0),$A13,"") | AE13: =IF(AND($A13>=Premissas!$C$25,N(AB13)>=0),$A13,"")
A14: =DATE(YEAR(A13),MONTH(A13)+1,1) -> 46661 | B14: =IF($A14<Premissas!$C$25,"Obra",IF($A14=Premissas!$C$25,"Chaves",IF($A14<Premissas!$C$27,"Mobiliando","Airbnb"))) -> Obra | C14: =(YEAR($A14)-YEAR(Premissas!$C$18))*12+MONTH($A14)-MONTH(Premissas!$C$18) -> 13 | D14: =($A14=Premissas!$C$19)*Premissas!$C$8+(($A14=EDATE(Premissas!$C$19,1))+($A14=EDATE(Premissas!$C$19,2)))*Premissas!$C$9+AND($A14>=Premissas!$C$20,$A14<EDATE(Premissas!$C$20,Premissas!$C$21))*Premissas!$C$10+(($A14=Premissas!$C$22)+($A14=Premissas!$C$23)+($A14=Premissas!$C$24))*Premissas!$C$11+($A14=Premissas!$C$25)*Premissas!$C$12 -> 1530 | E14: =(1+Premissas!$C$57)^C14 -> 1.0597176 | F14: =D14*E14 -> 1621.368 | G14: =($A14=Premissas!$C$25)*Premissas!$C$34*Premissas!$C$14*(1+Premissas!$C$57)^C14 -> 0 | H14: =IF(AND($A14>Premissas!$C$25,$A14<Premissas!$C$27),Premissas!$C$35/MAX(1,Premissas!$C$26),0) -> 0 | I14: =IF(AND($A14>Premissas!$C$25,((YEAR($A14)-YEAR(Premissas!$C$25))*12+MONTH($A14)-MONTH(Premissas!$C$25))<=Premissas!$C$32),((YEAR($A14)-YEAR(Premissas!$C$25))*12+MONTH($A14)-MONTH(Premissas!$C$25)),0) -> 0 | J14: =IF(I14>0,N13*(1+Premissas!$C$59),0) -> 0 | K14: =J14*Premissas!$C$58 -> 0 | L14: =IF(I14>0,J14/(Premissas!$C$32-I14+1),0) -> 0 | M14: =K14+L14 -> 0 | N14: =IF($A14=Premissas!$C$25,Premissas!$C$13*E14,IF(I14>0,J14-L14,0)) -> 0 | O14: =IF($A14>=Premissas!$C$27,Premissas!$C$39*IF(((YEAR($A14)-YEAR(Premissas!$C$27))*12+MONTH($A14)-MONTH(Premissas!$C$27))<Premissas!$C$41,Premissas!$C$42,1),0) -> 0 | P14: =O14*Premissas!$C$38*Premissas!$C$40*(1+Premissas!$C$60)^((YEAR($A14)-YEAR(Premissas!$C$19))*12+MONTH($A14)-MONTH(Premissas!$C$19)) -> 0 | Q14: =P14*Premissas!$C$43 -> 0 | R14: =P14*Premissas!$C$44 -> 0 | S14: =IF($A14>=Premissas!$C$25,Premissas!$C$45*(1+Premissas!$C$60)^((YEAR($A14)-YEAR(Premissas!$C$19))*12+MONTH($A14)-MONTH(Premissas!$C$19)),0) -> 0 | T14: =IF($A14>=Premissas!$C$27,Premissas!$C$46*(1+Premissas!$C$60)^((YEAR($A14)-YEAR(Premissas!$C$19))*12+MONTH($A14)-MONTH(Premissas!$C$19)),0) -> 0 | U14: =IF($A14>=Premissas!$C$27,Premissas!$C$47*(1+Premissas!$C$60)^((YEAR($A14)-YEAR(Premissas!$C$19))*12+MONTH($A14)-MONTH(Premissas!$C$19)),0) -> 0 | V14: =IF($A14>=Premissas!$C$27,MAX(0,P14-Q14-R14-S14)*Premissas!$C$49,0) -> 0 | W14: =P14-Q14-R14-S14-T14-U14-V14 -> 0 | X14: =W14-F14-G14-H14-M14 -> -1621.368 | Y14: =Y13+X14 -> -82986.782 | Z14: =Premissas!$C$14*(1+Premissas!$C$57)^((YEAR(Premissas!$C$19)-YEAR(Premissas!$C$18))*12+MONTH(Premissas!$C$19)-MONTH(Premissas!$C$18))*(1+Premissas!$C$61)^((YEAR($A14)-YEAR(Premissas!$C$19))*12+MONTH($A14)-MONTH(Premissas!$C$19)) -> 496042.43 | AA14: =IF($A14>=Premissas!$C$25,Z14*(1-Premissas!$C$53)-N14-Premissas!$C$54*MAX(0,Z14*(1-Premissas!$C$53)-(Premissas!$C$14*(1+Premissas!$C$57)^((YEAR(Premissas!$C$25)-YEAR(Premissas!$C$18))*12+MONTH(Premissas!$C$25)-MONTH(Premissas!$C$18))*(1+Premissas!$C$34))),"") | AB14: =IF($A14>=Premissas!$C$25,Y14+AA14,"") | AC14: =IF(AND($A14>=Premissas!$C$27,W14>=M14),$A14,"") | AD14: =IF(AND($A14>=Premissas!$C$27,Y14>=0),$A14,"") | AE14: =IF(AND($A14>=Premissas!$C$25,N(AB14)>=0),$A14,"")
A15: =DATE(YEAR(A14),MONTH(A14)+1,1) -> 46692 | B15: =IF($A15<Premissas!$C$25,"Obra",IF($A15=Premissas!$C$25,"Chaves",IF($A15<Premissas!$C$27,"Mobiliando","Airbnb"))) -> Obra | C15: =(YEAR($A15)-YEAR(Premissas!$C$18))*12+MONTH($A15)-MONTH(Premissas!$C$18) -> 14 | D15: =($A15=Premissas!$C$19)*Premissas!$C$8+(($A15=EDATE(Premissas!$C$19,1))+($A15=EDATE(Premissas!$C$19,2)))*Premissas!$C$9+AND($A15>=Premissas!$C$20,$A15<EDATE(Premissas!$C$20,Premissas!$C$21))*Premissas!$C$10+(($A15=Premissas!$C$22)+($A15=Premissas!$C$23)+($A15=Premissas!$C$24))*Premissas!$C$11+($A15=Premissas!$C$25)*Premissas!$C$12 -> 1530 | E15: =(1+Premissas!$C$57)^C15 -> 1.0644564 | F15: =D15*E15 -> 1628.6183 | G15: =($A15=Premissas!$C$25)*Premissas!$C$34*Premissas!$C$14*(1+Premissas!$C$57)^C15 -> 0 | H15: =IF(AND($A15>Premissas!$C$25,$A15<Premissas!$C$27),Premissas!$C$35/MAX(1,Premissas!$C$26),0) -> 0 | I15: =IF(AND($A15>Premissas!$C$25,((YEAR($A15)-YEAR(Premissas!$C$25))*12+MONTH($A15)-MONTH(Premissas!$C$25))<=Premissas!$C$32),((YEAR($A15)-YEAR(Premissas!$C$25))*12+MONTH($A15)-MONTH(Premissas!$C$25)),0) -> 0 | J15: =IF(I15>0,N14*(1+Premissas!$C$59),0) -> 0 | K15: =J15*Premissas!$C$58 -> 0 | L15: =IF(I15>0,J15/(Premissas!$C$32-I15+1),0) -> 0 | M15: =K15+L15 -> 0 | N15: =IF($A15=Premissas!$C$25,Premissas!$C$13*E15,IF(I15>0,J15-L15,0)) -> 0 | O15: =IF($A15>=Premissas!$C$27,Premissas!$C$39*IF(((YEAR($A15)-YEAR(Premissas!$C$27))*12+MONTH($A15)-MONTH(Premissas!$C$27))<Premissas!$C$41,Premissas!$C$42,1),0) -> 0 | P15: =O15*Premissas!$C$38*Premissas!$C$40*(1+Premissas!$C$60)^((YEAR($A15)-YEAR(Premissas!$C$19))*12+MONTH($A15)-MONTH(Premissas!$C$19)) -> 0 | Q15: =P15*Premissas!$C$43 -> 0 | R15: =P15*Premissas!$C$44 -> 0 | S15: =IF($A15>=Premissas!$C$25,Premissas!$C$45*(1+Premissas!$C$60)^((YEAR($A15)-YEAR(Premissas!$C$19))*12+MONTH($A15)-MONTH(Premissas!$C$19)),0) -> 0 | T15: =IF($A15>=Premissas!$C$27,Premissas!$C$46*(1+Premissas!$C$60)^((YEAR($A15)-YEAR(Premissas!$C$19))*12+MONTH($A15)-MONTH(Premissas!$C$19)),0) -> 0 | U15: =IF($A15>=Premissas!$C$27,Premissas!$C$47*(1+Premissas!$C$60)^((YEAR($A15)-YEAR(Premissas!$C$19))*12+MONTH($A15)-MONTH(Premissas!$C$19)),0) -> 0 | V15: =IF($A15>=Premissas!$C$27,MAX(0,P15-Q15-R15-S15)*Premissas!$C$49,0) -> 0 | W15: =P15-Q15-R15-S15-T15-U15-V15 -> 0 | X15: =W15-F15-G15-H15-M15 -> -1628.6183 | Y15: =Y14+X15 -> -84615.4 | Z15: =Premissas!$C$14*(1+Premissas!$C$57)^((YEAR(Premissas!$C$19)-YEAR(Premissas!$C$18))*12+MONTH(Premissas!$C$19)-MONTH(Premissas!$C$18))*(1+Premissas!$C$61)^((YEAR($A15)-YEAR(Premissas!$C$19))*12+MONTH($A15)-MONTH(Premissas!$C$19)) -> 498063.37 | AA15: =IF($A15>=Premissas!$C$25,Z15*(1-Premissas!$C$53)-N15-Premissas!$C$54*MAX(0,Z15*(1-Premissas!$C$53)-(Premissas!$C$14*(1+Premissas!$C$57)^((YEAR(Premissas!$C$25)-YEAR(Premissas!$C$18))*12+MONTH(Premissas!$C$25)-MONTH(Premissas!$C$18))*(1+Premissas!$C$34))),"") | AB15: =IF($A15>=Premissas!$C$25,Y15+AA15,"") | AC15: =IF(AND($A15>=Premissas!$C$27,W15>=M15),$A15,"") | AD15: =IF(AND($A15>=Premissas!$C$27,Y15>=0),$A15,"") | AE15: =IF(AND($A15>=Premissas!$C$25,N(AB15)>=0),$A15,"")
A16: =DATE(YEAR(A15),MONTH(A15)+1,1) -> 46722 | B16: =IF($A16<Premissas!$C$25,"Obra",IF($A16=Premissas!$C$25,"Chaves",IF($A16<Premissas!$C$27,"Mobiliando","Airbnb"))) -> Obra | C16: =(YEAR($A16)-YEAR(Premissas!$C$18))*12+MONTH($A16)-MONTH(Premissas!$C$18) -> 15 | D16: =($A16=Premissas!$C$19)*Premissas!$C$8+(($A16=EDATE(Premissas!$C$19,1))+($A16=EDATE(Premissas!$C$19,2)))*Premissas!$C$9+AND($A16>=Premissas!$C$20,$A16<EDATE(Premissas!$C$20,Premissas!$C$21))*Premissas!$C$10+(($A16=Premissas!$C$22)+($A16=Premissas!$C$23)+($A16=Premissas!$C$24))*Premissas!$C$11+($A16=Premissas!$C$25)*Premissas!$C$12 -> 10610 | E16: =(1+Premissas!$C$57)^C16 -> 1.0692163 | F16: =D16*E16 -> 11344.385 | G16: =($A16=Premissas!$C$25)*Premissas!$C$34*Premissas!$C$14*(1+Premissas!$C$57)^C16 -> 0 | H16: =IF(AND($A16>Premissas!$C$25,$A16<Premissas!$C$27),Premissas!$C$35/MAX(1,Premissas!$C$26),0) -> 0 | I16: =IF(AND($A16>Premissas!$C$25,((YEAR($A16)-YEAR(Premissas!$C$25))*12+MONTH($A16)-MONTH(Premissas!$C$25))<=Premissas!$C$32),((YEAR($A16)-YEAR(Premissas!$C$25))*12+MONTH($A16)-MONTH(Premissas!$C$25)),0) -> 0 | J16: =IF(I16>0,N15*(1+Premissas!$C$59),0) -> 0 | K16: =J16*Premissas!$C$58 -> 0 | L16: =IF(I16>0,J16/(Premissas!$C$32-I16+1),0) -> 0 | M16: =K16+L16 -> 0 | N16: =IF($A16=Premissas!$C$25,Premissas!$C$13*E16,IF(I16>0,J16-L16,0)) -> 0 | O16: =IF($A16>=Premissas!$C$27,Premissas!$C$39*IF(((YEAR($A16)-YEAR(Premissas!$C$27))*12+MONTH($A16)-MONTH(Premissas!$C$27))<Premissas!$C$41,Premissas!$C$42,1),0) -> 0 | P16: =O16*Premissas!$C$38*Premissas!$C$40*(1+Premissas!$C$60)^((YEAR($A16)-YEAR(Premissas!$C$19))*12+MONTH($A16)-MONTH(Premissas!$C$19)) -> 0 | Q16: =P16*Premissas!$C$43 -> 0 | R16: =P16*Premissas!$C$44 -> 0 | S16: =IF($A16>=Premissas!$C$25,Premissas!$C$45*(1+Premissas!$C$60)^((YEAR($A16)-YEAR(Premissas!$C$19))*12+MONTH($A16)-MONTH(Premissas!$C$19)),0) -> 0 | T16: =IF($A16>=Premissas!$C$27,Premissas!$C$46*(1+Premissas!$C$60)^((YEAR($A16)-YEAR(Premissas!$C$19))*12+MONTH($A16)-MONTH(Premissas!$C$19)),0) -> 0 | U16: =IF($A16>=Premissas!$C$27,Premissas!$C$47*(1+Premissas!$C$60)^((YEAR($A16)-YEAR(Premissas!$C$19))*12+MONTH($A16)-MONTH(Premissas!$C$19)),0) -> 0 | V16: =IF($A16>=Premissas!$C$27,MAX(0,P16-Q16-R16-S16)*Premissas!$C$49,0) -> 0 | W16: =P16-Q16-R16-S16-T16-U16-V16 -> 0 | X16: =W16-F16-G16-H16-M16 -> -11344.385 | Y16: =Y15+X16 -> -95959.785 | Z16: =Premissas!$C$14*(1+Premissas!$C$57)^((YEAR(Premissas!$C$19)-YEAR(Premissas!$C$18))*12+MONTH(Premissas!$C$19)-MONTH(Premissas!$C$18))*(1+Premissas!$C$61)^((YEAR($A16)-YEAR(Premissas!$C$19))*12+MONTH($A16)-MONTH(Premissas!$C$19)) -> 500092.54 | AA16: =IF($A16>=Premissas!$C$25,Z16*(1-Premissas!$C$53)-N16-Premissas!$C$54*MAX(0,Z16*(1-Premissas!$C$53)-(Premissas!$C$14*(1+Premissas!$C$57)^((YEAR(Premissas!$C$25)-YEAR(Premissas!$C$18))*12+MONTH(Premissas!$C$25)-MONTH(Premissas!$C$18))*(1+Premissas!$C$34))),"") | AB16: =IF($A16>=Premissas!$C$25,Y16+AA16,"") | AC16: =IF(AND($A16>=Premissas!$C$27,W16>=M16),$A16,"") | AD16: =IF(AND($A16>=Premissas!$C$27,Y16>=0),$A16,"") | AE16: =IF(AND($A16>=Premissas!$C$25,N(AB16)>=0),$A16,"")
A17: =DATE(YEAR(A16),MONTH(A16)+1,1) -> 46753 | B17: =IF($A17<Premissas!$C$25,"Obra",IF($A17=Premissas!$C$25,"Chaves",IF($A17<Premissas!$C$27,"Mobiliando","Airbnb"))) -> Obra | C17: =(YEAR($A17)-YEAR(Premissas!$C$18))*12+MONTH($A17)-MONTH(Premissas!$C$18) -> 16 | D17: =($A17=Premissas!$C$19)*Premissas!$C$8+(($A17=EDATE(Premissas!$C$19,1))+($A17=EDATE(Premissas!$C$19,2)))*Premissas!$C$9+AND($A17>=Premissas!$C$20,$A17<EDATE(Premissas!$C$20,Premissas!$C$21))*Premissas!$C$10+(($A17=Premissas!$C$22)+($A17=Premissas!$C$23)+($A17=Premissas!$C$24))*Premissas!$C$11+($A17=Premissas!$C$25)*Premissas!$C$12 -> 1530 | E17: =(1+Premissas!$C$57)^C17 -> 1.0739975 | F17: =D17*E17 -> 1643.2162 | G17: =($A17=Premissas!$C$25)*Premissas!$C$34*Premissas!$C$14*(1+Premissas!$C$57)^C17 -> 0 | H17: =IF(AND($A17>Premissas!$C$25,$A17<Premissas!$C$27),Premissas!$C$35/MAX(1,Premissas!$C$26),0) -> 0 | I17: =IF(AND($A17>Premissas!$C$25,((YEAR($A17)-YEAR(Premissas!$C$25))*12+MONTH($A17)-MONTH(Premissas!$C$25))<=Premissas!$C$32),((YEAR($A17)-YEAR(Premissas!$C$25))*12+MONTH($A17)-MONTH(Premissas!$C$25)),0) -> 0 | J17: =IF(I17>0,N16*(1+Premissas!$C$59),0) -> 0 | K17: =J17*Premissas!$C$58 -> 0 | L17: =IF(I17>0,J17/(Premissas!$C$32-I17+1),0) -> 0 | M17: =K17+L17 -> 0 | N17: =IF($A17=Premissas!$C$25,Premissas!$C$13*E17,IF(I17>0,J17-L17,0)) -> 0 | O17: =IF($A17>=Premissas!$C$27,Premissas!$C$39*IF(((YEAR($A17)-YEAR(Premissas!$C$27))*12+MONTH($A17)-MONTH(Premissas!$C$27))<Premissas!$C$41,Premissas!$C$42,1),0) -> 0 | P17: =O17*Premissas!$C$38*Premissas!$C$40*(1+Premissas!$C$60)^((YEAR($A17)-YEAR(Premissas!$C$19))*12+MONTH($A17)-MONTH(Premissas!$C$19)) -> 0 | Q17: =P17*Premissas!$C$43 -> 0 | R17: =P17*Premissas!$C$44 -> 0 | S17: =IF($A17>=Premissas!$C$25,Premissas!$C$45*(1+Premissas!$C$60)^((YEAR($A17)-YEAR(Premissas!$C$19))*12+MONTH($A17)-MONTH(Premissas!$C$19)),0) -> 0 | T17: =IF($A17>=Premissas!$C$27,Premissas!$C$46*(1+Premissas!$C$60)^((YEAR($A17)-YEAR(Premissas!$C$19))*12+MONTH($A17)-MONTH(Premissas!$C$19)),0) -> 0 | U17: =IF($A17>=Premissas!$C$27,Premissas!$C$47*(1+Premissas!$C$60)^((YEAR($A17)-YEAR(Premissas!$C$19))*12+MONTH($A17)-MONTH(Premissas!$C$19)),0) -> 0 | V17: =IF($A17>=Premissas!$C$27,MAX(0,P17-Q17-R17-S17)*Premissas!$C$49,0) -> 0 | W17: =P17-Q17-R17-S17-T17-U17-V17 -> 0 | X17: =W17-F17-G17-H17-M17 -> -1643.2162 | Y17: =Y16+X17 -> -97603.001 | Z17: =Premissas!$C$14*(1+Premissas!$C$57)^((YEAR(Premissas!$C$19)-YEAR(Premissas!$C$18))*12+MONTH(Premissas!$C$19)-MONTH(Premissas!$C$18))*(1+Premissas!$C$61)^((YEAR($A17)-YEAR(Premissas!$C$19))*12+MONTH($A17)-MONTH(Premissas!$C$19)) -> 502129.98 | AA17: =IF($A17>=Premissas!$C$25,Z17*(1-Premissas!$C$53)-N17-Premissas!$C$54*MAX(0,Z17*(1-Premissas!$C$53)-(Premissas!$C$14*(1+Premissas!$C$57)^((YEAR(Premissas!$C$25)-YEAR(Premissas!$C$18))*12+MONTH(Premissas!$C$25)-MONTH(Premissas!$C$18))*(1+Premissas!$C$34))),"") | AB17: =IF($A17>=Premissas!$C$25,Y17+AA17,"") | AC17: =IF(AND($A17>=Premissas!$C$27,W17>=M17),$A17,"") | AD17: =IF(AND($A17>=Premissas!$C$27,Y17>=0),$A17,"") | AE17: =IF(AND($A17>=Premissas!$C$25,N(AB17)>=0),$A17,"")
... A388: =DATE(YEAR(A387),MONTH(A387)+1,1) -> 58045 | B388: =IF($A388<Premissas!$C$25,"Obra",IF($A388=Premissas!$C$25,"Chaves",IF($A388<Premissas!$C$27,"Mobiliando","Airbnb"))) -> Airbnb | C388: =(YEAR($A388)-YEAR(Premissas!$C$18))*12+MONTH($A388)-MONTH(Premissas!$C$18) -> 387 | D388: =($A388=Premissas!$C$19)*Premissas!$C$8+(($A388=EDATE(Premissas!$C$19,1))+($A388=EDATE(Premissas!$C$19,2)))*Premissas!$C$9+AND($A388>=Premissas!$C$20,$A388<EDATE(Premissas!$C$20,Premissas!$C$21))*Premissas!$C$10+(($A388=Premissas!$C$22)+($A388=Premissas!$C$23)+($A388=Premissas!$C$24))*Premissas!$C$11+($A388=Premissas!$C$25)*Premissas!$C$12 -> 0 | E388: =(1+Premissas!$C$57)^C388 -> 5.6220127 | F388: =D388*E388 -> 0 | G388: =($A388=Premissas!$C$25)*Premissas!$C$34*Premissas!$C$14*(1+Premissas!$C$57)^C388 -> 0 | H388: =IF(AND($A388>Premissas!$C$25,$A388<Premissas!$C$27),Premissas!$C$35/MAX(1,Premissas!$C$26),0) -> 0 | I388: =IF(AND($A388>Premissas!$C$25,((YEAR($A388)-YEAR(Premissas!$C$25))*12+MONTH($A388)-MONTH(Premissas!$C$25))<=Premissas!$C$32),((YEAR($A388)-YEAR(Premissas!$C$25))*12+MONTH($A388)-MONTH(Premissas!$C$25)),0) -> 0 | J388: =IF(I388>0,N387*(1+Premissas!$C$59),0) -> 0 | K388: =J388*Premissas!$C$58 -> 0 | L388: =IF(I388>0,J388/(Premissas!$C$32-I388+1),0) -> 0 | M388: =K388+L388 -> 0 | N388: =IF($A388=Premissas!$C$25,Premissas!$C$13*E388,IF(I388>0,J388-L388,0)) -> 0 | O388: =IF($A388>=Premissas!$C$27,Premissas!$C$39*IF(((YEAR($A388)-YEAR(Premissas!$C$27))*12+MONTH($A388)-MONTH(Premissas!$C$27))<Premissas!$C$41,Premissas!$C$42,1),0) -> 0.62 | P388: =O388*Premissas!$C$38*Premissas!$C$40*(1+Premissas!$C$60)^((YEAR($A388)-YEAR(Premissas!$C$19))*12+MONTH($A388)-MONTH(Premissas!$C$19)) -> 14958.505 | Q388: =P388*Premissas!$C$43 -> 2393.3608 | R388: =P388*Premissas!$C$44 -> 2991.701 | S388: =IF($A388>=Premissas!$C$25,Premissas!$C$45*(1+Premissas!$C$60)^((YEAR($A388)-YEAR(Premissas!$C$19))*12+MONTH($A388)-MONTH(Premissas!$C$19)),0) -> 2622.4588 | T388: =IF($A388>=Premissas!$C$27,Premissas!$C$46*(1+Premissas!$C$60)^((YEAR($A388)-YEAR(Premissas!$C$19))*12+MONTH($A388)-MONTH(Premissas!$C$19)),0) -> 1048.9835 | U388: =IF($A388>=Premissas!$C$27,Premissas!$C$47*(1+Premissas!$C$60)^((YEAR($A388)-YEAR(Premissas!$C$19))*12+MONTH($A388)-MONTH(Premissas!$C$19)),0) -> 524.49176 | V388: =IF($A388>=Premissas!$C$27,MAX(0,P388-Q388-R388-S388)*Premissas!$C$49,0) -> 1911.5207 | W388: =P388-Q388-R388-S388-T388-U388-V388 -> 3465.9884 | X388: =W388-F388-G388-H388-M388 -> 3465.9884 | Y388: =Y387+X388 -> -159360.83 | Z388: =Premissas!$C$14*(1+Premissas!$C$57)^((YEAR(Premissas!$C$19)-YEAR(Premissas!$C$18))*12+MONTH(Premissas!$C$19)-MONTH(Premissas!$C$18))*(1+Premissas!$C$61)^((YEAR($A388)-YEAR(Premissas!$C$19))*12+MONTH($A388)-MONTH(Premissas!$C$19)) -> 2269439.7 | AA388: =IF($A388>=Premissas!$C$25,Z388*(1-Premissas!$C$53)-N388-Premissas!$C$54*MAX(0,Z388*(1-Premissas!$C$53)-(Premissas!$C$14*(1+Premissas!$C$57)^((YEAR(Premissas!$C$25)-YEAR(Premissas!$C$18))*12+MONTH(Premissas!$C$25)-MONTH(Premissas!$C$18))*(1+Premissas!$C$34))),"") -> 1894484.5 | AB388: =IF($A388>=Premissas!$C$25,Y388+AA388,"") -> 1735123.7 | AC388: =IF(AND($A388>=Premissas!$C$27,W388>=M388),$A388,"") -> 58045 | AD388: =IF(AND($A388>=Premissas!$C$27,Y388>=0),$A388,"") | AE388: =IF(AND($A388>=Premissas!$C$25,N(AB388)>=0),$A388,"") -> 58045
