Workbook

Sheet Resumo
A1: SCP Haddock Lobo - estudo de caso do studio
A2: Compara as 4 formas de pagamento da tabela. Sem financiamento: tudo é pago até a entrega. Imóvel vendido (líquido) x mesmo dinheiro aplicado no CDI (líquido de IR).
A4: Unidade | B4: =Premissas!$C$6 -> 308
A5: Área (m²) | B5: =Premissas!$C$7 -> 18.09
A6: Previsão de lançamento (mar/27) | B6: =Premissas!$C$8 -> 432401
A7: Valor de mercado estimado na entrega | B7: =Premissas!$C$60 -> 411668.06
A8: … R$/m² na entrega | B8: =Premissas!$C$61 -> 22756.664
A9: Entrega das chaves (premissa) | B9: =Premissas!$C$18 -> 47635
A10: Início do Airbnb | B10: =Premissas!$C$20 -> 47727
A11: Resultado mensal do imóvel após IR (1º mês pós ramp-up) | B11: =INDEX('Fluxo mensal'!$L$5:$L$355,MATCH(EDATE(Premissas!$C$20,Premissas!$C$33),'Fluxo mensal'!$A$5:$A$355,0)) -> 1522.0762
A13: Indicador | B13: Promo à vista | C13: À vista | D13: 3x | E13: 20% + 43x
A14: Total pago à SCP | B14: =SUM('Fluxo mensal'!$Q$5:$Q$355) -> 250000 | C14: =SUM('Fluxo mensal'!$W$5:$W$355) -> 280928 | D14: =SUM('Fluxo mensal'!$AC$5:$AC$355) -> 288548.46 | E14: =SUM('Fluxo mensal'!$AI$5:$AI$355) -> 334412.95
A15: Desembolso total até o início do Airbnb (SCP + ITBI + mobília) | B15: =-INDEX('Fluxo mensal'!$S$5:$S$355,MATCH(Premissas!$C$20,'Fluxo mensal'!$A$5:$A$355,0)) -> 305551.04 | C15: =-INDEX('Fluxo mensal'!$Y$5:$Y$355,MATCH(Premissas!$C$20,'Fluxo mensal'!$A$5:$A$355,0)) -> 336479.04 | D15: =-INDEX('Fluxo mensal'!$AE$5:$AE$355,MATCH(Premissas!$C$20,'Fluxo mensal'!$A$5:$A$355,0)) -> 344099.51 | E15: =-INDEX('Fluxo mensal'!$AK$5:$AK$355,MATCH(Premissas!$C$20,'Fluxo mensal'!$A$5:$A$355,0)) -> 389963.99
A16: Ganho no papel na entrega (posição se vender na entrega) | B16: =INDEX('Fluxo mensal'!$U$5:$U$355,MATCH(EDATE(Premissas!$C$18,0),'Fluxo mensal'!$A$5:$A$355,0)) -> 89233.266 | C16: =INDEX('Fluxo mensal'!$AA$5:$AA$355,MATCH(EDATE(Premissas!$C$18,0),'Fluxo mensal'!$A$5:$A$355,0)) -> 62944.466 | D16: =INDEX('Fluxo mensal'!$AG$5:$AG$355,MATCH(EDATE(Premissas!$C$18,0),'Fluxo mensal'!$A$5:$A$355,0)) -> 56467.072 | E16: =INDEX('Fluxo mensal'!$AM$5:$AM$355,MATCH(EDATE(Premissas!$C$18,0),'Fluxo mensal'!$A$5:$A$355,0)) -> 17482.259
A17: Retorno do aluguel sobre o desembolso (a.a., 1º ano pleno) | B17: =12*INDEX('Fluxo mensal'!$L$5:$L$355,MATCH(EDATE(Premissas!$C$20,Premissas!$C$33),'Fluxo mensal'!$A$5:$A$355,0))/-INDEX('Fluxo mensal'!$S$5:$S$355,MATCH(Premissas!$C$20,'Fluxo mensal'!$A$5:$A$355,0)) -> 0.059776967 | C17: =12*INDEX('Fluxo mensal'!$L$5:$L$355,MATCH(EDATE(Premissas!$C$20,Premissas!$C$33),'Fluxo mensal'!$A$5:$A$355,0))/-INDEX('Fluxo mensal'!$Y$5:$Y$355,MATCH(Premissas!$C$20,'Fluxo mensal'!$A$5:$A$355,0)) -> 0.054282473 | D17: =12*INDEX('Fluxo mensal'!$L$5:$L$355,MATCH(EDATE(Premissas!$C$20,Premissas!$C$33),'Fluxo mensal'!$A$5:$A$355,0))/-INDEX('Fluxo mensal'!$AE$5:$AE$355,MATCH(Premissas!$C$20,'Fluxo mensal'!$A$5:$A$355,0)) -> 0.053080327 | E17: =12*INDEX('Fluxo mensal'!$L$5:$L$355,MATCH(EDATE(Premissas!$C$20,Premissas!$C$33),'Fluxo mensal'!$A$5:$A$355,0))/-INDEX('Fluxo mensal'!$AK$5:$AK$355,MATCH(Premissas!$C$20,'Fluxo mensal'!$A$5:$A$355,0)) -> 0.046837438
A18: Break-even de caixa (aluguel devolve tudo que saiu) | B18: =IFERROR(INDEX('Fluxo mensal'!$A$5:$A$355,MATCH(1,INDEX(('Fluxo mensal'!$S$5:$S$355>=0)*('Fluxo mensal'!$A$5:$A$355>=Premissas!$C$20),0),0)),"Não atinge até 2055") -> 52505 | C18: =IFERROR(INDEX('Fluxo mensal'!$A$5:$A$355,MATCH(1,INDEX(('Fluxo mensal'!$Y$5:$Y$355>=0)*('Fluxo mensal'!$A$5:$A$355>=Premissas!$C$20),0),0)),"Não atinge até 2055") -> 52871 | D18: =IFERROR(INDEX('Fluxo mensal'!$A$5:$A$355,MATCH(1,INDEX(('Fluxo mensal'!$AE$5:$AE$355>=0)*('Fluxo mensal'!$A$5:$A$355>=Premissas!$C$20),0),0)),"Não atinge até 2055") -> 52963 | E18: =IFERROR(INDEX('Fluxo mensal'!$A$5:$A$355,MATCH(1,INDEX(('Fluxo mensal'!$AK$5:$AK$355>=0)*('Fluxo mensal'!$A$5:$A$355>=Premissas!$C$20),0),0)),"Não atinge até 2055") -> 53448
A19: Imóvel: posição se vender 5 anos após a entrega | B19: =INDEX('Fluxo mensal'!$U$5:$U$355,MATCH(EDATE(Premissas!$C$18,60),'Fluxo mensal'!$A$5:$A$355,0)) -> 246784.31 | C19: =INDEX('Fluxo mensal'!$AA$5:$AA$355,MATCH(EDATE(Premissas!$C$18,60),'Fluxo mensal'!$A$5:$A$355,0)) -> 220495.51 | D19: =INDEX('Fluxo mensal'!$AG$5:$AG$355,MATCH(EDATE(Premissas!$C$18,60),'Fluxo mensal'!$A$5:$A$355,0)) -> 214018.11 | E19: =INDEX('Fluxo mensal'!$AM$5:$AM$355,MATCH(EDATE(Premissas!$C$18,60),'Fluxo mensal'!$A$5:$A$355,0)) -> 175033.3
A20: CDI: saldo líquido no mesmo momento (5 anos) | B20: =INDEX('Fluxo mensal'!$V$5:$V$355,MATCH(EDATE(Premissas!$C$18,60),'Fluxo mensal'!$A$5:$A$355,0))+INDEX('Fluxo mensal'!$S$5:$S$355,MATCH(EDATE(Premissas!$C$18,60),'Fluxo mensal'!$A$5:$A$355,0)) -> 282310.83 | C20: =INDEX('Fluxo mensal'!$AB$5:$AB$355,MATCH(EDATE(Premissas!$C$18,60),'Fluxo mensal'!$A$5:$A$355,0))+INDEX('Fluxo mensal'!$Y$5:$Y$355,MATCH(EDATE(Premissas!$C$18,60),'Fluxo mensal'!$A$5:$A$355,0)) -> 316165.01 | D20: =INDEX('Fluxo mensal'!$AH$5:$AH$355,MATCH(EDATE(Premissas!$C$18,60),'Fluxo mensal'!$A$5:$A$355,0))+INDEX('Fluxo mensal'!$AE$5:$AE$355,MATCH(EDATE(Premissas!$C$18,60),'Fluxo mensal'!$A$5:$A$355,0)) -> 318870.77 | E20: =INDEX('Fluxo mensal'!$AN$5:$AN$355,MATCH(EDATE(Premissas!$C$18,60),'Fluxo mensal'!$A$5:$A$355,0))+INDEX('Fluxo mensal'!$AK$5:$AK$355,MATCH(EDATE(Premissas!$C$18,60),'Fluxo mensal'!$A$5:$A$355,0)) -> 282641.25
A21: Imóvel: posição se vender 10 anos após a entrega | B21: =INDEX('Fluxo mensal'!$U$5:$U$355,MATCH(EDATE(Premissas!$C$18,120),'Fluxo mensal'!$A$5:$A$355,0)) -> 483333.16 | C21: =INDEX('Fluxo mensal'!$AA$5:$AA$355,MATCH(EDATE(Premissas!$C$18,120),'Fluxo mensal'!$A$5:$A$355,0)) -> 457044.36 | D21: =INDEX('Fluxo mensal'!$AG$5:$AG$355,MATCH(EDATE(Premissas!$C$18,120),'Fluxo mensal'!$A$5:$A$355,0)) -> 450566.96 | E21: =INDEX('Fluxo mensal'!$AM$5:$AM$355,MATCH(EDATE(Premissas!$C$18,120),'Fluxo mensal'!$A$5:$A$355,0)) -> 411582.15
A22: CDI: saldo líquido no mesmo momento (10 anos) | B22: =INDEX('Fluxo mensal'!$V$5:$V$355,MATCH(EDATE(Premissas!$C$18,120),'Fluxo mensal'!$A$5:$A$355,0))+INDEX('Fluxo mensal'!$S$5:$S$355,MATCH(EDATE(Premissas!$C$18,120),'Fluxo mensal'!$A$5:$A$355,0)) -> 504955.14 | C22: =INDEX('Fluxo mensal'!$AB$5:$AB$355,MATCH(EDATE(Premissas!$C$18,120),'Fluxo mensal'!$A$5:$A$355,0))+INDEX('Fluxo mensal'!$Y$5:$Y$355,MATCH(EDATE(Premissas!$C$18,120),'Fluxo mensal'!$A$5:$A$355,0)) -> 571437.3 | D22: =INDEX('Fluxo mensal'!$AH$5:$AH$355,MATCH(EDATE(Premissas!$C$18,120),'Fluxo mensal'!$A$5:$A$355,0))+INDEX('Fluxo mensal'!$AE$5:$AE$355,MATCH(EDATE(Premissas!$C$18,120),'Fluxo mensal'!$A$5:$A$355,0)) -> 579343.94 | E22: =INDEX('Fluxo mensal'!$AN$5:$AN$355,MATCH(EDATE(Premissas!$C$18,120),'Fluxo mensal'!$A$5:$A$355,0))+INDEX('Fluxo mensal'!$AK$5:$AK$355,MATCH(EDATE(Premissas!$C$18,120),'Fluxo mensal'!$A$5:$A$355,0)) -> 547967.13
A23: Imóvel: posição se vender 20 anos após a entrega | B23: =INDEX('Fluxo mensal'!$U$5:$U$355,MATCH(EDATE(Premissas!$C$18,240),'Fluxo mensal'!$A$5:$A$355,0)) -> 1145437.8 | C23: =INDEX('Fluxo mensal'!$AA$5:$AA$355,MATCH(EDATE(Premissas!$C$18,240),'Fluxo mensal'!$A$5:$A$355,0)) -> 1119149 | D23: =INDEX('Fluxo mensal'!$AG$5:$AG$355,MATCH(EDATE(Premissas!$C$18,240),'Fluxo mensal'!$A$5:$A$355,0)) -> 1112671.6 | E23: =INDEX('Fluxo mensal'!$AM$5:$AM$355,MATCH(EDATE(Premissas!$C$18,240),'Fluxo mensal'!$A$5:$A$355,0)) -> 1073686.8
A24: CDI: saldo líquido no mesmo momento (20 anos) | B24: =INDEX('Fluxo mensal'!$V$5:$V$355,MATCH(EDATE(Premissas!$C$18,240),'Fluxo mensal'!$A$5:$A$355,0))+INDEX('Fluxo mensal'!$S$5:$S$355,MATCH(EDATE(Premissas!$C$18,240),'Fluxo mensal'!$A$5:$A$355,0)) -> 1095605.9 | C24: =INDEX('Fluxo mensal'!$AB$5:$AB$355,MATCH(EDATE(Premissas!$C$18,240),'Fluxo mensal'!$A$5:$A$355,0))+INDEX('Fluxo mensal'!$Y$5:$Y$355,MATCH(EDATE(Premissas!$C$18,240),'Fluxo mensal'!$A$5:$A$355,0)) -> 1284920.7 | D24: =INDEX('Fluxo mensal'!$AH$5:$AH$355,MATCH(EDATE(Premissas!$C$18,240),'Fluxo mensal'!$A$5:$A$355,0))+INDEX('Fluxo mensal'!$AE$5:$AE$355,MATCH(EDATE(Premissas!$C$18,240),'Fluxo mensal'!$A$5:$A$355,0)) -> 1312406.7 | E24: =INDEX('Fluxo mensal'!$AN$5:$AN$355,MATCH(EDATE(Premissas!$C$18,240),'Fluxo mensal'!$A$5:$A$355,0))+INDEX('Fluxo mensal'!$AK$5:$AK$355,MATCH(EDATE(Premissas!$C$18,240),'Fluxo mensal'!$A$5:$A$355,0)) -> 1299298.7
A26: Como ler:
A27: • Posição total = caixa acumulado (tudo que saiu e entrou) + o que sobraria vendendo (após corretagem e IR sobre ganho).
A28: • Linhas CDI: o mesmo dinheiro tirado do bolso aplicado no CDI (líquido de 15% de IR), na mesma régua da posição do imóvel.
A29: • Riscos fora da planilha: SCP antes do registro de incorporação (sem patrimônio de afetação), aprovação do projeto, atraso, regulação CVM, liquidez da cota.
A30: • Datas e correção das parcelas não constam da tabela: confirmar com a incorporadora (abas Premissas, seções 2 e 3).

Sheet Premissas
A1: Premissas - SCP Haddock Lobo
A2: Edite só as células em azul (amarelo = premissas que mais mexem no resultado).
A5: 1. Unidade
A6: Unidade escolhida (lista) | C6: 308 | D6: Padrão: 308 (18,09 m², tem promo de R$ 250 mil = menor R$/m² entre os studios de ~18 m²)
A7: Área (m²) | C7: =INDEX('Tabela SCP'!$D$4:$D$125,MATCH(Premissas!$C$6,'Tabela SCP'!$A$4:$A$125,0)) -> 18.09
A8: Previsão de lançamento (mar/27) | C8: =INDEX('Tabela SCP'!$E$4:$E$125,MATCH(Premissas!$C$6,'Tabela SCP'!$A$4:$A$125,0)) -> 432401
A9: SCP à vista (out/26) | C9: =INDEX('Tabela SCP'!$F$4:$F$125,MATCH(Premissas!$C$6,'Tabela SCP'!$A$4:$A$125,0)) -> 280928
A10: 3x SCP (total) | C10: =INDEX('Tabela SCP'!$G$4:$G$125,MATCH(Premissas!$C$6,'Tabela SCP'!$A$4:$A$125,0)) -> 287262
A11: Ato 20% + 43x SCP (total) | C11: =INDEX('Tabela SCP'!$H$4:$H$125,MATCH(Premissas!$C$6,'Tabela SCP'!$A$4:$A$125,0)) -> 308538
A12: Promo à vista (0 = sem promo para esta unidade) | C12: =N(INDEX('Tabela SCP'!$I$4:$I$125,MATCH(Premissas!$C$6,'Tabela SCP'!$A$4:$A$125,0))) -> 250000
A13: Promo à vista usada no estudo | C13: =IF(Premissas!$C$12>0,Premissas!$C$12,Premissas!$C$9) -> 250000 | D13: Se a unidade não tem promo, usa o preço SCP à vista
A15: 2. Datas
A16: Data da compra (adesão à SCP) | C16: 46296 | D16: Tabela válida em out/26
A17: Lançamento previsto | C17: 46447 | D17: Tabela: previsão mar/27
A18: Entrega das chaves | C18: 47635 | D18: PREMISSA: a tabela não informa. Lançamento mar/27 + ~39 meses; o 43x termina em mai/30
A19: Meses para mobiliar | C19: 2
A20: Início do Airbnb | C20: =DATE(YEAR(Premissas!$C$18),MONTH(Premissas!$C$18)+Premissas!$C$19+1,1) -> 47727
A22: 3. Correções e custos de aquisição
A23: Correção das parcelas SCP (a.a.) | C23: 0.055 | D23: PREMISSA: a tabela não informa. Usei INCC ~5,5%. Se for valor fixo, use 0
A24: INCC até a entrega (corrige o preço de lançamento) | C24: 0.055
A25: Valor de mercado na entrega (% da tabela de lançamento corrigida) | C25: 0.8 | D25: PREMISSA-CHAVE: revenda de studio costuma sair abaixo da tabela da incorporadora. 100% = vale o preço de lançamento
A26: ITBI + registro na entrega (% do valor de mercado) | C26: 0.04 | D26: Entrega da unidade ao sócio tende a ser dação em pagamento: ITBI sobre o valor de referência
A27: Mobília, decoração e enxoval | C27: 25000 | D27: Studio de ~18 m²
A29: 4. Operação Airbnb (valores de hoje)
A30: Diária média | C30: 250 | D30: Jardins/Consolação, studio: R$ 220-320 (estudo). Haddock Lobo fica entre Paulista e Oscar Freire
A31: Ocupação média | C31: 0.62 | D31: Mediana SP 61-63%
A32: Dias por mês | C32: 30
A33: Meses de ramp-up | C33: 3
A34: Ocupação no ramp-up (% da média) | C34: 0.6
A35: Taxa Airbnb | C35: 0.16
A36: Gestora (% da receita) | C36: 0.2
A37: Condomínio + IPTU (mês) | C37: 600 | D37: Estimativa para ~18 m² em prédio novo com amenities
A38: Contas (luz, internet, streaming, amenities) | C38: 280
A39: Manutenção e reposição | C39: 150
A40: Inflação de diária e custos (a.a.) | C40: 0.04
A41: IR sobre aluguel (alíquota marginal) | C41: 0.275 | D41: Carnê-leão; deduz Airbnb, gestora, condomínio e IPTU
A43: 5. Valorização e venda
A44: Valorização após a entrega (a.a.) | C44: 0.05 | D44: SP: +3,8% em 12 meses (FipeZap jul/26)
A45: Corretagem na venda | C45: 0.06
A46: IR sobre ganho de capital | C46: 0.15
...

Sheet Tabela SCP
A1: SCP Haddock Lobo - tabela out/26 (extraída do PDF enviado pelo usuário)
A3: Unidade | B3: Tipologia | C3: Andar | D3: Área (m²) | E3: Previsão lançamento mar/27 | F3: SCP à vista out/26 | G3: 3x SCP | H3: Ato 20% + 43x SCP | I3: Promo à vista | J3: SCP R$/m² à vista | K3: Desconto SCP vs lançamento
A4: 102 | B4: Studio | C4: 1 | D4: 16.47 | E4: 393679 | F4: 255770 | G4: 261537 | H4: 280908 | J4: 15529 | K4: =1-MIN(F4,IF(I4>0,I4,F4))/E4 -> 0.35030825
A5: 103 | B5: Studio | C5: 1 | D5: 17.73 | E5: 423796 | F5: 275337 | G5: 281545 | H5: 302398 | J5: 15529 | K5: =1-MIN(F5,IF(I5>0,I5,F5))/E5 -> 0.3503077
A6: 104 | B6: Studio | C6: 1 | D6: 18.16 | E6: 434075 | F6: 282015 | G6: 288373 | H6: 309732 | J6: 15529 | K6: =1-MIN(F6,IF(I6>0,I6,F6))/E6 -> 0.35030813
A7: 106 | B7: Studio | C7: 1 | D7: 18.16 | E7: 434075 | F7: 282015 | G7: 288373 | H7: 309732 | J7: 15529 | K7: =1-MIN(F7,IF(I7>0,I7,F7))/E7 -> 0.35030813
A8: 107 | B8: Studio | C8: 1 | D8: 17.73 | E8: 423796 | F8: 275337 | G8: 281545 | H8: 302398 | J8: 15529 | K8: =1-MIN(F8,IF(I8>0,I8,F8))/E8 -> 0.3503077
A9: 108 | B9: Studio | C9: 1 | D9: 18.09 | E9: 432401 | F9: 280928 | G9: 287262 | H9: 308538 | J9: 15529 | K9: =1-MIN(F9,IF(I9>0,I9,F9))/E9 -> 0.35030678
A10: 109 | B10: Studio | C10: 1 | D10: 18.09 | E10: 432401 | F10: 280928 | G10: 287262 | H10: 308538 | J10: 15529 | K10: =1-MIN(F10,IF(I10>0,I10,F10))/E10 -> 0.35030678
A11: 202 | B11: Studio | C11: 2 | D11: 16.47 | E11: 393679 | F11: 255770 | G11: 261537 | H11: 280908 | J11: 15529 | K11: =1-MIN(F11,IF(I11>0,I11,F11))/E11 -> 0.35030825
A12: 203 | B12: Studio | C12: 2 | D12: 17.73 | E12: 423796 | F12: 275337 | G12: 281545 | H12: 302398 | J12: 15529 | K12: =1-MIN(F12,IF(I12>0,I12,F12))/E12 -> 0.3503077
A13: 204 | B13: Studio | C13: 2 | D13: 17.76 | E13: 424513 | F13: 275803 | G13: 282022 | H13: 302909 | J13: 15529 | K13: =1-MIN(F13,IF(I13>0,I13,F13))/E13 -> 0.35030729
A14: 205 | B14: Studio | C14: 2 | D14: 20.72 | E14: 460712 | F14: 299321 | G14: 306070 | H14: 328739 | J14: 14446 | K14: =1-MIN(F14,IF(I14>0,I14,F14))/E14 -> 0.35030778
A15: 206 | B15: Studio | C15: 2 | D15: 17.78 | E15: 424991 | F15: 276114 | G15: 282339 | H15: 303251 | J15: 15529 | K15: =1-MIN(F15,IF(I15>0,I15,F15))/E15 -> 0.35030624
... A18: 209 | B18: Studio | C18: 2 | D18: 18.09 | E18: 432401 | F18: 280928 | G18: 287262 | H18: 308538 | J18: 15529 | K18: =1-MIN(F18,IF(I18>0,I18,F18))/E18 -> 0.35030678
A19: 301 | B19: Studio | C19: 3 | D19: 17.08 | E19: 408260 | F19: 265243 | G19: 271223 | H19: 291312 | I19: 250000 | J19: 14637 | K19: =1-MIN(F19,IF(I19>0,I19,F19))/E19 -> 0.38764513
A20: 302 | B20: Studio | C20: 3 | D20: 16.47 | E20: 393679 | F20: 255770 | G20: 261537 | H20: 280908 | I20: 250000 | J20: 15179 | K20: =1-MIN(F20,IF(I20>0,I20,F20))/E20 -> 0.36496486
A21: 303 | B21: Studio | C21: 3 | D21: 17.73 | E21: 423796 | F21: 275337 | G21: 281545 | H21: 302398 | I21: 250000 | J21: 14100 | K21: =1-MIN(F21,IF(I21>0,I21,F21))/E21 -> 0.41009354
A22: 304 | B22: Studio | C22: 3 | D22: 17.76 | E22: 424513 | F22: 275803 | G22: 282022 | H22: 302909 | I22: 250000 | J22: 14077 | K22: =1-MIN(F22,IF(I22>0,I22,F22))/E22 -> 0.41108988
A23: 306 | B23: Studio | C23: 3 | D23: 17.78 | E23: 424991 | F23: 276114 | G23: 282339 | H23: 303251 | I23: 250000 | J23: 14061 | K23: =1-MIN(F23,IF(I23>0,I23,F23))/E23 -> 0.41175225
A24: 307 | B24: Studio | C24: 3 | D24: 17.73 | E24: 423796 | F24: 275337 | G24: 281545 | H24: 302398 | I24: 250000 | J24: 14100 | K24: =1-MIN(F24,IF(I24>0,I24,F24))/E24 -> 0.41009354
A25: 308 | B25: Studio | C25: 3 | D25: 18.09 | E25: 432401 | F25: 280928 | G25: 287262 | H25: 308538 | I25: 250000 | J25: 13820 | K25: =1-MIN(F25,IF(I25>0,I25,F25))/E25 -> 0.42183297
A26: 309 | B26: Studio | C26: 3 | D26: 18.09 | E26: 432401 | F26: 280928 | G26: 287262 | H26: 308538 | I26: 250000 | J26: 13820 | K26: =1-MIN(F26,IF(I26>0,I26,F26))/E26 -> 0.42183297
A27: 401 | B27: Studio | C27: 4 | D27: 17.08 | E27: 408260 | F27: 265243 | G27: 271223 | H27: 291312 | I27: 250000 | J27: 14637 | K27: =1-MIN(F27,IF(I27>0,I27,F27))/E27 -> 0.38764513
A28: 403 | B28: Studio | C28: 4 | D28: 17.73 | E28: 423796 | F28: 275337 | G28: 281545 | H28: 302398 | I28: 250000 | J28: 14100 | K28: =1-MIN(F28,IF(I28>0,I28,F28))/E28 -> 0.41009354
A29: 405 | B29: Studio | C29: 4 | D29: 20.72 | E29: 460712 | F29: 299321 | G29: 306070 | H29: 328739 | J29: 14446 | K29: =1-MIN(F29,IF(I29>0,I29,F29))/E29 -> 0.35030778
A30: 406 | B30: Studio | C30: 4 | D30: 17.78 | E30: 424991 | F30: 276114 | G30: 282339 | H30: 303251 | I30: 250000 | J30: 14061 | K30: =1-MIN(F30,IF(I30>0,I30,F30))/E30 -> 0.41175225
A31: 408 | B31: Studio | C31: 4 | D31: 18.09 | E31: 432401 | F31: 280928 | G31: 287262 | H31: 308538 | I31: 250000 | J31: 13820 | K31: =1-MIN(F31,IF(I31>0,I31,F31))/E31 -> 0.42183297
A32: 409 | B32: Studio | C32: 4 | D32: 18.09 | E32: 432401 | F32: 280928 | G32: 287262 | H32: 308538 | I32: 250000 | J32: 13820 | K32: =1-MIN(F32,IF(I32>0,I32,F32))/E32 -> 0.42183297
A33: 501 | B33: Studio | C33: 5 | D33: 17.08 | E33: 415115 | F33: 269697 | G33: 275778 | H33: 296203 | I33: 250000 | J33: 14637 | K33: =1-MIN(F33,IF(I33>0,I33,F33))/E33 -> 0.39775725
A34: 502 | B34: Studio | C34: 5 | D34: 16.47 | E34: 400289 | F34: 260065 | G34: 265928 | H34: 285624 | J34: 15790 | K34: =1-MIN(F34,IF(I34>0,I34,F34))/E34 -> 0.3503069
A35: 504 | B35: Studio | C35: 5 | D35: 17.76 | E35: 431642 | F35: 280434 | G35: 286757 | H35: 307996 | I35: 250000 | J35: 14077 | K35: =1-MIN(F35,IF(I35>0,I35,F35))/E35 -> 0.42081632
A36: 505 | B36: Studio | C36: 5 | D36: 20.72 | E36: 468448 | F36: 304347 | G36: 311209 | H36: 334259 | I36: 250000 | J36: 12066 | K36: =1-MIN(F36,IF(I36>0,I36,F36))/E36 -> 0.46632284
A37: 507 | B37: Studio | C37: 5 | D37: 17.73 | E37: 430912 | F37: 279961 | G37: 286273 | H37: 307475 | I37: 250000 | J37: 14100 | K37: =1-MIN(F37,IF(I37>0,I37,F37))/E37 -> 0.41983514
A38: 509 | B38: Studio | C38: 5 | D38: 18.09 | E38: 439662 | F38: 285645 | G38: 292085 | H38: 313719 | I38: 250000 | J38: 13820 | K38: =1-MIN(F38,IF(I38>0,I38,F38))/E38 -> 0.43138138
A39: 602 | B39: Studio | C39: 6 | D39: 16.47 | E39: 400289 | F39: 260065 | G39: 265928 | H39: 285624 | I39: 250000 | J39: 15179 | K39: =1-MIN(F39,IF(I39>0,I39,F39))/E39 -> 0.37545124
A40: 605 | B40: Studio | C40: 6 | D40: 20.72 | E40: 468448 | F40: 304347 | G40: 311209 | H40: 334259 | J40: 14689 | K40: =1-MIN(F40,IF(I40>0,I40,F40))/E40 -> 0.35030782
A41: 607 | B41: Studio | C41: 6 | D41: 17.73 | E41: 430912 | F41: 279961 | G41: 286273 | H41: 307475 | I41: 250000 | J41: 14100 | K41: =1-MIN(F41,IF(I41>0,I41,F41))/E41 -> 0.41983514
A42: 703 | B42: Studio | C42: 7 | D42: 17.73 | E42: 430912 | F42: 279961 | G42: 286273 | H42: 307475 | J42: 15790 | K42: =1-MIN(F42,IF(I42>0,I42,F42))/E42 -> 0.35030586
A43: 705 | B43: Studio | C43: 7 | D43: 20.72 | E43: 468448 | F43: 304347 | G43: 311209 | H43: 334259 | J43: 14689 | K43: =1-MIN(F43,IF(I43>0,I43,F43))/E43 -> 0.35030782
...

Sheet Fluxo mensal
A1: Fluxo mensal - SCP Haddock Lobo (R$ nominais; saídas negativas)
A4: Mês | B4: Fase | C4: Meses desde a compra | D4: Ocupação | E4: Receita bruta | F4: Taxa Airbnb | G4: Gestora | H4: Condomínio + IPTU | I4: Contas | J4: Manutenção | K4: IR | L4: Resultado do imóvel (após IR) | M4: ITBI + registro | N4: Mobília | O4: Valor de mercado | P4: CDI líquido (mês) | Q4: Promo à vista: Pagamento SCP | R4: Promo à vista: Fluxo de caixa | S4: Promo à vista: Caixa acumulado | T4: Promo à vista: Patrimônio se vender | U4: Promo à vista: Posição total | V4: Promo à vista: Saldo em CDI (espelho) | W4: À vista: Pagamento SCP | X4: À vista: Fluxo de caixa | Y4: À vista: Caixa acumulado | Z4: À vista: Patrimônio se vender | AA4: À vista: Posição total | AB4: À vista: Saldo em CDI (espelho) | AC4: 3x: Pagamento SCP | AD4: 3x: Fluxo de caixa | AE4: 3x: Caixa acumulado | AF4: 3x: Patrimônio se vender | AG4: 3x: Posição total | AH4: 3x: Saldo em CDI (espelho) | AI4: 20% + 43x: Pagamento SCP | AJ4: 20% + 43x: Fluxo de caixa | AK4: 20% + 43x: Caixa acumulado | AL4: 20% + 43x: Patrimônio se vender | AM4: 20% + 43x: Posição total | AN4: 20% + 43x: Saldo em CDI (espelho) | AO4: Promo: CDI na régua da posição (saldo + caixa)
A5: =Premissas!$C$16 -> 46296 | B5: =IF($A5<Premissas!$C$18,"Obra",IF($A5<Premissas!$C$20,"Entrega/mobília","Airbnb")) -> Obra | C5: =(YEAR($A5)-YEAR(Premissas!$C$16))*12+MONTH($A5)-MONTH(Premissas!$C$16) -> 0 | D5: =IF($A5>=Premissas!$C$20,Premissas!$C$31*IF(((YEAR($A5)-YEAR(Premissas!$C$20))*12+MONTH($A5)-MONTH(Premissas!$C$20))<Premissas!$C$33,Premissas!$C$34,1),0) -> 0 | E5: =D5*Premissas!$C$30*Premissas!$C$32*(1+Premissas!$C$58)^$C5 -> 0 | F5: =E5*Premissas!$C$35 -> 0 | G5: =E5*Premissas!$C$36 -> 0 | H5: =IF($A5>=Premissas!$C$18,Premissas!$C$37*(1+Premissas!$C$58)^$C5,0) -> 0 | I5: =IF($A5>=Premissas!$C$20,Premissas!$C$38*(1+Premissas!$C$58)^$C5,0) -> 0 | J5: =IF($A5>=Premissas!$C$20,Premissas!$C$39*(1+Premissas!$C$58)^$C5,0) -> 0 | K5: =IF($A5>=Premissas!$C$20,MAX(0,E5-F5-G5-H5)*Premissas!$C$41,0) -> 0 | L5: =E5-F5-G5-H5-I5-J5-K5 -> 0 | M5: =($A5=Premissas!$C$18)*Premissas!$C$26*Premissas!$C$60 -> 0 | N5: =IF(AND($A5>=Premissas!$C$18,$A5<Premissas!$C$20),Premissas!$C$27/MAX(1,Premissas!$C$19),0) -> 0 | O5: =IF($A5>=Premissas!$C$18,Premissas!$C$60*(1+Premissas!$C$59)^((YEAR($A5)-YEAR(Premissas!$C$18))*12+MONTH($A5)-MONTH(Premissas!$C$18)),"") | P5: =(1+IF(YEAR($A5)<=2026,Premissas!$C$49,IF(YEAR($A5)=2027,Premissas!$C$50,IF(YEAR($A5)=2028,Premissas!$C$51,Premissas!$C$52)))*(1-Premissas!$C$53))^(1/12)-1 -> 0.0094136514 | Q5: =($A5=Premissas!$C$16)*Premissas!$C$13 -> 250000 | R5: =L5-M5-N5-Q5 -> -250000 | S5: =R5 -> -250000 | T5: =IF($A5>=Premissas!$C$18,O5*(1-Premissas!$C$45)-Premissas!$C$46*MAX(0,O5*(1-Premissas!$C$45)-(SUM($Q$5:$Q$355)+Premissas!$C$26*Premissas!$C$60)),"") | U5: =IF($A5>=Premissas!$C$18,S5+T5,"") | V5: =0*(1+$P5)-R5 -> 250000 | W5: =($A5=Premissas!$C$16)*Premissas!$C$9 -> 280928 | X5: =L5-M5-N5-W5 -> -280928 | Y5: =X5 -> -280928 | Z5: =IF($A5>=Premissas!$C$18,O5*(1-Premissas!$C$45)-Premissas!$C$46*MAX(0,O5*(1-Premissas!$C$45)-(SUM($W$5:$W$355)+Premissas!$C$26*Premissas!$C$60)),"") | AA5: =IF($A5>=Premissas!$C$18,Y5+Z5,"") | AB5: =0*(1+$P5)-X5 -> 280928 | AC5: =AND($A5>=Premissas!$C$16,$A5<EDATE(Premissas!$C$16,3))*Premissas!$C$10/3*(1+Premissas!$C$56)^$C5 -> 95754 | AD5: =L5-M5-N5-AC5 -> -95754 | AE5: =AD5 -> -95754 | AF5: =IF($A5>=Premissas!$C$18,O5*(1-Premissas!$C$45)-Premissas!$C$46*MAX(0,O5*(1-Premissas!$C$45)-(SUM($AC$5:$AC$355)+Premissas!$C$26*Premissas!$C$60)),"") | AG5: =IF($A5>=Premissas!$C$18,AE5+AF5,"") | AH5: =0*(1+$P5)-AD5 -> 95754 | AI5: =($A5=Premissas!$C$16)*0.2*Premissas!$C$11+AND($A5>Premissas!$C$16,$A5<=EDATE(Premissas!$C$16,43))*0.8*Premissas!$C$11/43*(1+Premissas!$C$56)^$C5 -> 61707.6 | AJ5: =L5-M5-N5-AI5 -> -61707.6 | AK5: =AJ5 -> -61707.6 | AL5: =IF($A5>=Premissas!$C$18,O5*(1-Premissas!$C$45)-Premissas!$C$46*MAX(0,O5*(1-Premissas!$C$45)-(SUM($AI$5:$AI$355)+Premissas!$C$26*Premissas!$C$60)),"") | AM5: =IF($A5>=Premissas!$C$18,AK5+AL5,"") | AN5: =0*(1+$P5)-AJ5 -> 61707.6 | AO5: =V5+S5 -> 0
A6: =DATE(YEAR(A5),MONTH(A5)+1,1) -> 46327 | B6: =IF($A6<Premissas!$C$18,"Obra",IF($A6<Premissas!$C$20,"Entrega/mobília","Airbnb")) -> Obra | C6: =(YEAR($A6)-YEAR(Premissas!$C$16))*12+MONTH($A6)-MONTH(Premissas!$C$16) -> 1 | D6: =IF($A6>=Premissas!$C$20,Premissas!$C$31*IF(((YEAR($A6)-YEAR(Premissas!$C$20))*12+MONTH($A6)-MONTH(Premissas!$C$20))<Premissas!$C$33,Premissas!$C$34,1),0) -> 0 | E6: =D6*Premissas!$C$30*Premissas!$C$32*(1+Premissas!$C$58)^$C6 -> 0 | F6: =E6*Premissas!$C$35 -> 0 | G6: =E6*Premissas!$C$36 -> 0 | H6: =IF($A6>=Premissas!$C$18,Premissas!$C$37*(1+Premissas!$C$58)^$C6,0) -> 0 | I6: =IF($A6>=Premissas!$C$20,Premissas!$C$38*(1+Premissas!$C$58)^$C6,0) -> 0 | J6: =IF($A6>=Premissas!$C$20,Premissas!$C$39*(1+Premissas!$C$58)^$C6,0) -> 0 | K6: =IF($A6>=Premissas!$C$20,MAX(0,E6-F6-G6-H6)*Premissas!$C$41,0) -> 0 | L6: =E6-F6-G6-H6-I6-J6-K6 -> 0 | M6: =($A6=Premissas!$C$18)*Premissas!$C$26*Premissas!$C$60 -> 0 | N6: =IF(AND($A6>=Premissas!$C$18,$A6<Premissas!$C$20),Premissas!$C$27/MAX(1,Premissas!$C$19),0) -> 0 | O6: =IF($A6>=Premissas!$C$18,Premissas!$C$60*(1+Premissas!$C$59)^((YEAR($A6)-YEAR(Premissas!$C$18))*12+MONTH($A6)-MONTH(Premissas!$C$18)),"") | P6: =(1+IF(YEAR($A6)<=2026,Premissas!$C$49,IF(YEAR($A6)=2027,Premissas!$C$50,IF(YEAR($A6)=2028,Premissas!$C$51,Premissas!$C$52)))*(1-Premissas!$C$53))^(1/12)-1 -> 0.0094136514 | Q6: =($A6=Premissas!$C$16)*Premissas!$C$13 -> 0 | R6: =L6-M6-N6-Q6 -> 0 | S6: =S5+R6 -> -250000 | T6: =IF($A6>=Premissas!$C$18,O6*(1-Premissas!$C$45)-Premissas!$C$46*MAX(0,O6*(1-Premissas!$C$45)-(SUM($Q$5:$Q$355)+Premissas!$C$26*Premissas!$C$60)),"") | U6: =IF($A6>=Premissas!$C$18,S6+T6,"") | V6: =V5*(1+$P6)-R6 -> 252353.41 | W6: =($A6=Premissas!$C$16)*Premissas!$C$9 -> 0 | X6: =L6-M6-N6-W6 -> 0 | Y6: =Y5+X6 -> -280928 | Z6: =IF($A6>=Premissas!$C$18,O6*(1-Premissas!$C$45)-Premissas!$C$46*MAX(0,O6*(1-Premissas!$C$45)-(SUM($W$5:$W$355)+Premissas!$C$26*Premissas!$C$60)),"") | AA6: =IF($A6>=Premissas!$C$18,Y6+Z6,"") | AB6: =AB5*(1+$P6)-X6 -> 283572.56 | AC6: =AND($A6>=Premissas!$C$16,$A6<EDATE(Premissas!$C$16,3))*Premissas!$C$10/3*(1+Premissas!$C$56)^$C6 -> 96182.183 | AD6: =L6-M6-N6-AC6 -> -96182.183 | AE6: =AE5+AD6 -> -191936.18 | AF6: =IF($A6>=Premissas!$C$18,O6*(1-Premissas!$C$45)-Premissas!$C$46*MAX(0,O6*(1-Premissas!$C$45)-(SUM($AC$5:$AC$355)+Premissas!$C$26*Premissas!$C$60)),"") | AG6: =IF($A6>=Premissas!$C$18,AE6+AF6,"") | AH6: =AH5*(1+$P6)-AD6 -> 192837.58 | AI6: =($A6=Premissas!$C$16)*0.2*Premissas!$C$11+AND($A6>Premissas!$C$16,$A6<=EDATE(Premissas!$C$16,43))*0.8*Premissas!$C$11/43*(1+Premissas!$C$56)^$C6 -> 5765.9105 | AJ6: =L6-M6-N6-AI6 -> -5765.9105 | AK6: =AK5+AJ6 -> -67473.51 | AL6: =IF($A6>=Premissas!$C$18,O6*(1-Premissas!$C$45)-Premissas!$C$46*MAX(0,O6*(1-Premissas!$C$45)-(SUM($AI$5:$AI$355)+Premissas!$C$26*Premissas!$C$60)),"") | AM6: =IF($A6>=Premissas!$C$18,AK6+AL6,"") | AN6: =AN5*(1+$P6)-AJ6 -> 68054.404 | AO6: =V6+S6 -> 2353.4129
A7: =DATE(YEAR(A6),MONTH(A6)+1,1) -> 46357 | B7: =IF($A7<Premissas!$C$18,"Obra",IF($A7<Premissas!$C$20,"Entrega/mobília","Airbnb")) -> Obra | C7: =(YEAR($A7)-YEAR(Premissas!$C$16))*12+MONTH($A7)-MONTH(Premissas!$C$16) -> 2 | D7: =IF($A7>=Premissas!$C$20,Premissas!$C$31*IF(((YEAR($A7)-YEAR(Premissas!$C$20))*12+MONTH($A7)-MONTH(Premissas!$C$20))<Premissas!$C$33,Premissas!$C$34,1),0) -> 0 | E7: =D7*Premissas!$C$30*Premissas!$C$32*(1+Premissas!$C$58)^$C7 -> 0 | F7: =E7*Premissas!$C$35 -> 0 | G7: =E7*Premissas!$C$36 -> 0 | H7: =IF($A7>=Premissas!$C$18,Premissas!$C$37*(1+Premissas!$C$58)^$C7,0) -> 0 | I7: =IF($A7>=Premissas!$C$20,Premissas!$C$38*(1+Premissas!$C$58)^$C7,0) -> 0 | J7: =IF($A7>=Premissas!$C$20,Premissas!$C$39*(1+Premissas!$C$58)^$C7,0) -> 0 | K7: =IF($A7>=Premissas!$C$20,MAX(0,E7-F7-G7-H7)*Premissas!$C$41,0) -> 0 | L7: =E7-F7-G7-H7-I7-J7-K7 -> 0 | M7: =($A7=Premissas!$C$18)*Premissas!$C$26*Premissas!$C$60 -> 0 | N7: =IF(AND($A7>=Premissas!$C$18,$A7<Premissas!$C$20),Premissas!$C$27/MAX(1,Premissas!$C$19),0) -> 0 | O7: =IF($A7>=Premissas!$C$18,Premissas!$C$60*(1+Premissas!$C$59)^((YEAR($A7)-YEAR(Premissas!$C$18))*12+MONTH($A7)-MONTH(Premissas!$C$18)),"") | P7: =(1+IF(YEAR($A7)<=2026,Premissas!$C$49,IF(YEAR($A7)=2027,Premissas!$C$50,IF(YEAR($A7)=2028,Premissas!$C$51,Premissas!$C$52)))*(1-Premissas!$C$53))^(1/12)-1 -> 0.0094136514 | Q7: =($A7=Premissas!$C$16)*Premissas!$C$13 -> 0 | R7: =L7-M7-N7-Q7 -> 0 | S7: =S6+R7 -> -250000 | T7: =IF($A7>=Premissas!$C$18,O7*(1-Premissas!$C$45)-Premissas!$C$46*MAX(0,O7*(1-Premissas!$C$45)-(SUM($Q$5:$Q$355)+Premissas!$C$26*Premissas!$C$60)),"") | U7: =IF($A7>=Premissas!$C$18,S7+T7,"") | V7: =V6*(1+$P7)-R7 -> 254728.98 | W7: =($A7=Premissas!$C$16)*Premissas!$C$9 -> 0 | X7: =L7-M7-N7-W7 -> 0 | Y7: =Y6+X7 -> -280928 | Z7: =IF($A7>=Premissas!$C$18,O7*(1-Premissas!$C$45)-Premissas!$C$46*MAX(0,O7*(1-Premissas!$C$45)-(SUM($W$5:$W$355)+Premissas!$C$26*Premissas!$C$60)),"") | AA7: =IF($A7>=Premissas!$C$18,Y7+Z7,"") | AB7: =AB6*(1+$P7)-X7 -> 286242.01 | AC7: =AND($A7>=Premissas!$C$16,$A7<EDATE(Premissas!$C$16,3))*Premissas!$C$10/3*(1+Premissas!$C$56)^$C7 -> 96612.281 | AD7: =L7-M7-N7-AC7 -> -96612.281 | AE7: =AE6+AD7 -> -288548.46 | AF7: =IF($A7>=Premissas!$C$18,O7*(1-Premissas!$C$45)-Premissas!$C$46*MAX(0,O7*(1-Premissas!$C$45)-(SUM($AC$5:$AC$355)+Premissas!$C$26*Premissas!$C$60)),"") | AG7: =IF($A7>=Premissas!$C$18,AE7+AF7,"") | AH7: =AH6*(1+$P7)-AD7 -> 291265.16 | AI7: =($A7=Premissas!$C$16)*0.2*Premissas!$C$11+AND($A7>Premissas!$C$16,$A7<=EDATE(Premissas!$C$16,43))*0.8*Premissas!$C$11/43*(1+Premissas!$C$56)^$C7 -> 5791.6939 | AJ7: =L7-M7-N7-AI7 -> -5791.6939 | AK7: =AK6+AJ7 -> -73265.204 | AL7: =IF($A7>=Premissas!$C$18,O7*(1-Premissas!$C$45)-Premissas!$C$46*MAX(0,O7*(1-Premissas!$C$45)-(SUM($AI$5:$AI$355)+Premissas!$C$26*Premissas!$C$60)),"") | AM7: =IF($A7>=Premissas!$C$18,AK7+AL7,"") | AN7: =AN6*(1+$P7)-AJ7 -> 74486.739 | AO7: =V7+S7 -> 4728.9799
A8: =DATE(YEAR(A7),MONTH(A7)+1,1) -> 46388 | B8: =IF($A8<Premissas!$C$18,"Obra",IF($A8<Premissas!$C$20,"Entrega/mobília","Airbnb")) -> Obra | C8: =(YEAR($A8)-YEAR(Premissas!$C$16))*12+MONTH($A8)-MONTH(Premissas!$C$16) -> 3 | D8: =IF($A8>=Premissas!$C$20,Premissas!$C$31*IF(((YEAR($A8)-YEAR(Premissas!$C$20))*12+MONTH($A8)-MONTH(Premissas!$C$20))<Premissas!$C$33,Premissas!$C$34,1),0) -> 0 | E8: =D8*Premissas!$C$30*Premissas!$C$32*(1+Premissas!$C$58)^$C8 -> 0 | F8: =E8*Premissas!$C$35 -> 0 | G8: =E8*Premissas!$C$36 -> 0 | H8: =IF($A8>=Premissas!$C$18,Premissas!$C$37*(1+Premissas!$C$58)^$C8,0) -> 0 | I8: =IF($A8>=Premissas!$C$20,Premissas!$C$38*(1+Premissas!$C$58)^$C8,0) -> 0 | J8: =IF($A8>=Premissas!$C$20,Premissas!$C$39*(1+Premissas!$C$58)^$C8,0) -> 0 | K8: =IF($A8>=Premissas!$C$20,MAX(0,E8-F8-G8-H8)*Premissas!$C$41,0) -> 0 | L8: =E8-F8-G8-H8-I8-J8-K8 -> 0 | M8: =($A8=Premissas!$C$18)*Premissas!$C$26*Premissas!$C$60 -> 0 | N8: =IF(AND($A8>=Premissas!$C$18,$A8<Premissas!$C$20),Premissas!$C$27/MAX(1,Premissas!$C$19),0) -> 0 | O8: =IF($A8>=Premissas!$C$18,Premissas!$C$60*(1+Premissas!$C$59)^((YEAR($A8)-YEAR(Premissas!$C$18))*12+MONTH($A8)-MONTH(Premissas!$C$18)),"") | P8: =(1+IF(YEAR($A8)<=2026,Premissas!$C$49,IF(YEAR($A8)=2027,Premissas!$C$50,IF(YEAR($A8)=2028,Premissas!$C$51,Premissas!$C$52)))*(1-Premissas!$C$53))^(1/12)-1 -> 0.0084501625 | Q8: =($A8=Premissas!$C$16)*Premissas!$C$13 -> 0 | R8: =L8-M8-N8-Q8 -> 0 | S8: =S7+R8 -> -250000 | T8: =IF($A8>=Premissas!$C$18,O8*(1-Premissas!$C$45)-Premissas!$C$46*MAX(0,O8*(1-Premissas!$C$45)-(SUM($Q$5:$Q$355)+Premissas!$C$26*Premissas!$C$60)),"") | U8: =IF($A8>=Premissas!$C$18,S8+T8,"") | V8: =V7*(1+$P8)-R8 -> 256881.48 | W8: =($A8=Premissas!$C$16)*Premissas!$C$9 -> 0 | X8: =L8-M8-N8-W8 -> 0 | Y8: =Y7+X8 -> -280928 | Z8: =IF($A8>=Premissas!$C$18,O8*(1-Premissas!$C$45)-Premissas!$C$46*MAX(0,O8*(1-Premissas!$C$45)-(SUM($W$5:$W$355)+Premissas!$C$26*Premissas!$C$60)),"") | AA8: =IF($A8>=Premissas!$C$18,Y8+Z8,"") | AB8: =AB7*(1+$P8)-X8 -> 288660.8 | AC8: =AND($A8>=Premissas!$C$16,$A8<EDATE(Premissas!$C$16,3))*Premissas!$C$10/3*(1+Premissas!$C$56)^$C8 -> 0 | AD8: =L8-M8-N8-AC8 -> 0 | AE8: =AE7+AD8 -> -288548.46 | AF8: =IF($A8>=Premissas!$C$18,O8*(1-Premissas!$C$45)-Premissas!$C$46*MAX(0,O8*(1-Premissas!$C$45)-(SUM($AC$5:$AC$355)+Premissas!$C$26*Premissas!$C$60)),"") | AG8: =IF($A8>=Premissas!$C$18,AE8+AF8,"") | AH8: =AH7*(1+$P8)-AD8 -> 293726.4 | AI8: =($A8=Premissas!$C$16)*0.2*Premissas!$C$11+AND($A8>Premissas!$C$16,$A8<=EDATE(Premissas!$C$16,43))*0.8*Premissas!$C$11/43*(1+Premissas!$C$56)^$C8 -> 5817.5926 | AJ8: =L8-M8-N8-AI8 -> -5817.5926 | AK8: =AK7+AJ8 -> -79082.797 | AL8: =IF($A8>=Premissas!$C$18,O8*(1-Premissas!$C$45)-Premissas!$C$46*MAX(0,O8*(1-Premissas!$C$45)-(SUM($AI$5:$AI$355)+Premissas!$C$26*Premissas!$C$60)),"") | AM8: =IF($A8>=Premissas!$C$18,AK8+AL8,"") | AN8: =AN7*(1+$P8)-AJ8 -> 80933.756 | AO8: =V8+S8 -> 6881.4812
A9: =DATE(YEAR(A8),MONTH(A8)+1,1) -> 46419 | B9: =IF($A9<Premissas!$C$18,"Obra",IF($A9<Premissas!$C$20,"Entrega/mobília","Airbnb")) -> Obra | C9: =(YEAR($A9)-YEAR(Premissas!$C$16))*12+MONTH($A9)-MONTH(Premissas!$C$16) -> 4 | D9: =IF($A9>=Premissas!$C$20,Premissas!$C$31*IF(((YEAR($A9)-YEAR(Premissas!$C$20))*12+MONTH($A9)-MONTH(Premissas!$C$20))<Premissas!$C$33,Premissas!$C$34,1),0) -> 0 | E9: =D9*Premissas!$C$30*Premissas!$C$32*(1+Premissas!$C$58)^$C9 -> 0 | F9: =E9*Premissas!$C$35 -> 0 | G9: =E9*Premissas!$C$36 -> 0 | H9: =IF($A9>=Premissas!$C$18,Premissas!$C$37*(1+Premissas!$C$58)^$C9,0) -> 0 | I9: =IF($A9>=Premissas!$C$20,Premissas!$C$38*(1+Premissas!$C$58)^$C9,0) -> 0 | J9: =IF($A9>=Premissas!$C$20,Premissas!$C$39*(1+Premissas!$C$58)^$C9,0) -> 0 | K9: =IF($A9>=Premissas!$C$20,MAX(0,E9-F9-G9-H9)*Premissas!$C$41,0) -> 0 | L9: =E9-F9-G9-H9-I9-J9-K9 -> 0 | M9: =($A9=Premissas!$C$18)*Premissas!$C$26*Premissas!$C$60 -> 0 | N9: =IF(AND($A9>=Premissas!$C$18,$A9<Premissas!$C$20),Premissas!$C$27/MAX(1,Premissas!$C$19),0) -> 0 | O9: =IF($A9>=Premissas!$C$18,Premissas!$C$60*(1+Premissas!$C$59)^((YEAR($A9)-YEAR(Premissas!$C$18))*12+MONTH($A9)-MONTH(Premissas!$C$18)),"") | P9: =(1+IF(YEAR($A9)<=2026,Premissas!$C$49,IF(YEAR($A9)=2027,Premissas!$C$50,IF(YEAR($A9)=2028,Premissas!$C$51,Premissas!$C$52)))*(1-Premissas!$C$53))^(1/12)-1 -> 0.0084501625 | Q9: =($A9=Premissas!$C$16)*Premissas!$C$13 -> 0 | R9: =L9-M9-N9-Q9 -> 0 | S9: =S8+R9 -> -250000 | T9: =IF($A9>=Premissas!$C$18,O9*(1-Premissas!$C$45)-Premissas!$C$46*MAX(0,O9*(1-Premissas!$C$45)-(SUM($Q$5:$Q$355)+Premissas!$C$26*Premissas!$C$60)),"") | U9: =IF($A9>=Premissas!$C$18,S9+T9,"") | V9: =V8*(1+$P9)-R9 -> 259052.17 | W9: =($A9=Premissas!$C$16)*Premissas!$C$9 -> 0 | X9: =L9-M9-N9-W9 -> 0 | Y9: =Y8+X9 -> -280928 | Z9: =IF($A9>=Premissas!$C$18,O9*(1-Premissas!$C$45)-Premissas!$C$46*MAX(0,O9*(1-Premissas!$C$45)-(SUM($W$5:$W$355)+Premissas!$C$26*Premissas!$C$60)),"") | AA9: =IF($A9>=Premissas!$C$18,Y9+Z9,"") | AB9: =AB8*(1+$P9)-X9 -> 291100.03 | AC9: =AND($A9>=Premissas!$C$16,$A9<EDATE(Premissas!$C$16,3))*Premissas!$C$10/3*(1+Premissas!$C$56)^$C9 -> 0 | AD9: =L9-M9-N9-AC9 -> 0 | AE9: =AE8+AD9 -> -288548.46 | AF9: =IF($A9>=Premissas!$C$18,O9*(1-Premissas!$C$45)-Premissas!$C$46*MAX(0,O9*(1-Premissas!$C$45)-(SUM($AC$5:$AC$355)+Premissas!$C$26*Premissas!$C$60)),"") | AG9: =IF($A9>=Premissas!$C$18,AE9+AF9,"") | AH9: =AH8*(1+$P9)-AD9 -> 296208.44 | AI9: =($A9=Premissas!$C$16)*0.2*Premissas!$C$11+AND($A9>Premissas!$C$16,$A9<=EDATE(Premissas!$C$16,43))*0.8*Premissas!$C$11/43*(1+Premissas!$C$56)^$C9 -> 5843.6071 | AJ9: =L9-M9-N9-AI9 -> -5843.6071 | AK9: =AK8+AJ9 -> -84926.404 | AL9: =IF($A9>=Premissas!$C$18,O9*(1-Premissas!$C$45)-Premissas!$C$46*MAX(0,O9*(1-Premissas!$C$45)-(SUM($AI$5:$AI$355)+Premissas!$C$26*Premissas!$C$60)),"") | AM9: =IF($A9>=Premissas!$C$18,AK9+AL9,"") | AN9: =AN8*(1+$P9)-AJ9 -> 87461.267 | AO9: =V9+S9 -> 9052.1715
A10: =DATE(YEAR(A9),MONTH(A9)+1,1) -> 46447 | B10: =IF($A10<Premissas!$C$18,"Obra",IF($A10<Premissas!$C$20,"Entrega/mobília","Airbnb")) -> Obra | C10: =(YEAR($A10)-YEAR(Premissas!$C$16))*12+MONTH($A10)-MONTH(Premissas!$C$16) -> 5 | D10: =IF($A10>=Premissas!$C$20,Premissas!$C$31*IF(((YEAR($A10)-YEAR(Premissas!$C$20))*12+MONTH($A10)-MONTH(Premissas!$C$20))<Premissas!$C$33,Premissas!$C$34,1),0) -> 0 | E10: =D10*Premissas!$C$30*Premissas!$C$32*(1+Premissas!$C$58)^$C10 -> 0 | F10: =E10*Premissas!$C$35 -> 0 | G10: =E10*Premissas!$C$36 -> 0 | H10: =IF($A10>=Premissas!$C$18,Premissas!$C$37*(1+Premissas!$C$58)^$C10,0) -> 0 | I10: =IF($A10>=Premissas!$C$20,Premissas!$C$38*(1+Premissas!$C$58)^$C10,0) -> 0 | J10: =IF($A10>=Premissas!$C$20,Premissas!$C$39*(1+Premissas!$C$58)^$C10,0) -> 0 | K10: =IF($A10>=Premissas!$C$20,MAX(0,E10-F10-G10-H10)*Premissas!$C$41,0) -> 0 | L10: =E10-F10-G10-H10-I10-J10-K10 -> 0 | M10: =($A10=Premissas!$C$18)*Premissas!$C$26*Premissas!$C$60 -> 0 | N10: =IF(AND($A10>=Premissas!$C$18,$A10<Premissas!$C$20),Premissas!$C$27/MAX(1,Premissas!$C$19),0) -> 0 | O10: =IF($A10>=Premissas!$C$18,Premissas!$C$60*(1+Premissas!$C$59)^((YEAR($A10)-YEAR(Premissas!$C$18))*12+MONTH($A10)-MONTH(Premissas!$C$18)),"") | P10: =(1+IF(YEAR($A10)<=2026,Premissas!$C$49,IF(YEAR($A10)=2027,Premissas!$C$50,IF(YEAR($A10)=2028,Premissas!$C$51,Premissas!$C$52)))*(1-Premissas!$C$53))^(1/12)-1 -> 0.0084501625 | Q10: =($A10=Premissas!$C$16)*Premissas!$C$13 -> 0 | R10: =L10-M10-N10-Q10 -> 0 | S10: =S9+R10 -> -250000 | T10: =IF($A10>=Premissas!$C$18,O10*(1-Premissas!$C$45)-Premissas!$C$46*MAX(0,O10*(1-Premissas!$C$45)-(SUM($Q$5:$Q$355)+Premissas!$C$26*Premissas!$C$60)),"") | U10: =IF($A10>=Premissas!$C$18,S10+T10,"") | V10: =V9*(1+$P10)-R10 -> 261241.2 | W10: =($A10=Premissas!$C$16)*Premissas!$C$9 -> 0 | X10: =L10-M10-N10-W10 -> 0 | Y10: =Y9+X10 -> -280928 | Z10: =IF($A10>=Premissas!$C$18,O10*(1-Premissas!$C$45)-Premissas!$C$46*MAX(0,O10*(1-Premissas!$C$45)-(SUM($W$5:$W$355)+Premissas!$C$26*Premissas!$C$60)),"") | AA10: =IF($A10>=Premissas!$C$18,Y10+Z10,"") | AB10: =AB9*(1+$P10)-X10 -> 293559.88 | AC10: =AND($A10>=Premissas!$C$16,$A10<EDATE(Premissas!$C$16,3))*Premissas!$C$10/3*(1+Premissas!$C$56)^$C10 -> 0 | AD10: =L10-M10-N10-AC10 -> 0 | AE10: =AE9+AD10 -> -288548.46 | AF10: =IF($A10>=Premissas!$C$18,O10*(1-Premissas!$C$45)-Premissas!$C$46*MAX(0,O10*(1-Premissas!$C$45)-(SUM($AC$5:$AC$355)+Premissas!$C$26*Premissas!$C$60)),"") | AG10: =IF($A10>=Premissas!$C$18,AE10+AF10,"") | AH10: =AH9*(1+$P10)-AD10 -> 298711.45 | AI10: =($A10=Premissas!$C$16)*0.2*Premissas!$C$11+AND($A10>Premissas!$C$16,$A10<=EDATE(Premissas!$C$16,43))*0.8*Premissas!$C$11/43*(1+Premissas!$C$56)^$C10 -> 5869.738 | AJ10: =L10-M10-N10-AI10 -> -5869.738 | AK10: =AK9+AJ10 -> -90796.142 | AL10: =IF($A10>=Premissas!$C$18,O10*(1-Premissas!$C$45)-Premissas!$C$46*MAX(0,O10*(1-Premissas!$C$45)-(SUM($AI$5:$AI$355)+Premissas!$C$26*Premissas!$C$60)),"") | AM10: =IF($A10>=Premissas!$C$18,AK10+AL10,"") | AN10: =AN9*(1+$P10)-AJ10 -> 94070.067 | AO10: =V10+S10 -> 11241.204
A11: =DATE(YEAR(A10),MONTH(A10)+1,1) -> 46478 | B11: =IF($A11<Premissas!$C$18,"Obra",IF($A11<Premissas!$C$20,"Entrega/mobília","Airbnb")) -> Obra | C11: =(YEAR($A11)-YEAR(Premissas!$C$16))*12+MONTH($A11)-MONTH(Premissas!$C$16) -> 6 | D11: =IF($A11>=Premissas!$C$20,Premissas!$C$31*IF(((YEAR($A11)-YEAR(Premissas!$C$20))*12+MONTH($A11)-MONTH(Premissas!$C$20))<Premissas!$C$33,Premissas!$C$34,1),0) -> 0 | E11: =D11*Premissas!$C$30*Premissas!$C$32*(1+Premissas!$C$58)^$C11 -> 0 | F11: =E11*Premissas!$C$35 -> 0 | G11: =E11*Premissas!$C$36 -> 0 | H11: =IF($A11>=Premissas!$C$18,Premissas!$C$37*(1+Premissas!$C$58)^$C11,0) -> 0 | I11: =IF($A11>=Premissas!$C$20,Premissas!$C$38*(1+Premissas!$C$58)^$C11,0) -> 0 | J11: =IF($A11>=Premissas!$C$20,Premissas!$C$39*(1+Premissas!$C$58)^$C11,0) -> 0 | K11: =IF($A11>=Premissas!$C$20,MAX(0,E11-F11-G11-H11)*Premissas!$C$41,0) -> 0 | L11: =E11-F11-G11-H11-I11-J11-K11 -> 0 | M11: =($A11=Premissas!$C$18)*Premissas!$C$26*Premissas!$C$60 -> 0 | N11: =IF(AND($A11>=Premissas!$C$18,$A11<Premissas!$C$20),Premissas!$C$27/MAX(1,Premissas!$C$19),0) -> 0 | O11: =IF($A11>=Premissas!$C$18,Premissas!$C$60*(1+Premissas!$C$59)^((YEAR($A11)-YEAR(Premissas!$C$18))*12+MONTH($A11)-MONTH(Premissas!$C$18)),"") | P11: =(1+IF(YEAR($A11)<=2026,Premissas!$C$49,IF(YEAR($A11)=2027,Premissas!$C$50,IF(YEAR($A11)=2028,Premissas!$C$51,Premissas!$C$52)))*(1-Premissas!$C$53))^(1/12)-1 -> 0.0084501625 | Q11: =($A11=Premissas!$C$16)*Premissas!$C$13 -> 0 | R11: =L11-M11-N11-Q11 -> 0 | S11: =S10+R11 -> -250000 | T11: =IF($A11>=Premissas!$C$18,O11*(1-Premissas!$C$45)-Premissas!$C$46*MAX(0,O11*(1-Premissas!$C$45)-(SUM($Q$5:$Q$355)+Premissas!$C$26*Premissas!$C$60)),"") | U11: =IF($A11>=Premissas!$C$18,S11+T11,"") | V11: =V10*(1+$P11)-R11 -> 263448.74 | W11: =($A11=Premissas!$C$16)*Premissas!$C$9 -> 0 | X11: =L11-M11-N11-W11 -> 0 | Y11: =Y10+X11 -> -280928 | Z11: =IF($A11>=Premissas!$C$18,O11*(1-Premissas!$C$45)-Premissas!$C$46*MAX(0,O11*(1-Premissas!$C$45)-(SUM($W$5:$W$355)+Premissas!$C$26*Premissas!$C$60)),"") | AA11: =IF($A11>=Premissas!$C$18,Y11+Z11,"") | AB11: =AB10*(1+$P11)-X11 -> 296040.5 | AC11: =AND($A11>=Premissas!$C$16,$A11<EDATE(Premissas!$C$16,3))*Premissas!$C$10/3*(1+Premissas!$C$56)^$C11 -> 0 | AD11: =L11-M11-N11-AC11 -> 0 | AE11: =AE10+AD11 -> -288548.46 | AF11: =IF($A11>=Premissas!$C$18,O11*(1-Premissas!$C$45)-Premissas!$C$46*MAX(0,O11*(1-Premissas!$C$45)-(SUM($AC$5:$AC$355)+Premissas!$C$26*Premissas!$C$60)),"") | AG11: =IF($A11>=Premissas!$C$18,AE11+AF11,"") | AH11: =AH10*(1+$P11)-AD11 -> 301235.61 | AI11: =($A11=Premissas!$C$16)*0.2*Premissas!$C$11+AND($A11>Premissas!$C$16,$A11<=EDATE(Premissas!$C$16,43))*0.8*Premissas!$C$11/43*(1+Premissas!$C$56)^$C11 -> 5895.9857 | AJ11: =L11-M11-N11-AI11 -> -5895.9857 | AK11: =AK10+AJ11 -> -96692.128 | AL11: =IF($A11>=Premissas!$C$18,O11*(1-Premissas!$C$45)-Premissas!$C$46*MAX(0,O11*(1-Premissas!$C$45)-(SUM($AI$5:$AI$355)+Premissas!$C$26*Premissas!$C$60)),"") | AM11: =IF($A11>=Premissas!$C$18,AK11+AL11,"") | AN11: =AN10*(1+$P11)-AJ11 -> 100760.96 | AO11: =V11+S11 -> 13448.735
A12: =DATE(YEAR(A11),MONTH(A11)+1,1) -> 46508 | B12: =IF($A12<Premissas!$C$18,"Obra",IF($A12<Premissas!$C$20,"Entrega/mobília","Airbnb")) -> Obra | C12: =(YEAR($A12)-YEAR(Premissas!$C$16))*12+MONTH($A12)-MONTH(Premissas!$C$16) -> 7 | D12: =IF($A12>=Premissas!$C$20,Premissas!$C$31*IF(((YEAR($A12)-YEAR(Premissas!$C$20))*12+MONTH($A12)-MONTH(Premissas!$C$20))<Premissas!$C$33,Premissas!$C$34,1),0) -> 0 | E12: =D12*Premissas!$C$30*Premissas!$C$32*(1+Premissas!$C$58)^$C12 -> 0 | F12: =E12*Premissas!$C$35 -> 0 | G12: =E12*Premissas!$C$36 -> 0 | H12: =IF($A12>=Premissas!$C$18,Premissas!$C$37*(1+Premissas!$C$58)^$C12,0) -> 0 | I12: =IF($A12>=Premissas!$C$20,Premissas!$C$38*(1+Premissas!$C$58)^$C12,0) -> 0 | J12: =IF($A12>=Premissas!$C$20,Premissas!$C$39*(1+Premissas!$C$58)^$C12,0) -> 0 | K12: =IF($A12>=Premissas!$C$20,MAX(0,E12-F12-G12-H12)*Premissas!$C$41,0) -> 0 | L12: =E12-F12-G12-H12-I12-J12-K12 -> 0 | M12: =($A12=Premissas!$C$18)*Premissas!$C$26*Premissas!$C$60 -> 0 | N12: =IF(AND($A12>=Premissas!$C$18,$A12<Premissas!$C$20),Premissas!$C$27/MAX(1,Premissas!$C$19),0) -> 0 | O12: =IF($A12>=Premissas!$C$18,Premissas!$C$60*(1+Premissas!$C$59)^((YEAR($A12)-YEAR(Premissas!$C$18))*12+MONTH($A12)-MONTH(Premissas!$C$18)),"") | P12: =(1+IF(YEAR($A12)<=2026,Premissas!$C$49,IF(YEAR($A12)=2027,Premissas!$C$50,IF(YEAR($A12)=2028,Premissas!$C$51,Premissas!$C$52)))*(1-Premissas!$C$53))^(1/12)-1 -> 0.0084501625 | Q12: =($A12=Premissas!$C$16)*Premissas!$C$13 -> 0 | R12: =L12-M12-N12-Q12 -> 0 | S12: =S11+R12 -> -250000 | T12: =IF($A12>=Premissas!$C$18,O12*(1-Premissas!$C$45)-Premissas!$C$46*MAX(0,O12*(1-Premissas!$C$45)-(SUM($Q$5:$Q$355)+Premissas!$C$26*Premissas!$C$60)),"") | U12: =IF($A12>=Premissas!$C$18,S12+T12,"") | V12: =V11*(1+$P12)-R12 -> 265674.92 | W12: =($A12=Premissas!$C$16)*Premissas!$C$9 -> 0 | X12: =L12-M12-N12-W12 -> 0 | Y12: =Y11+X12 -> -280928 | Z12: =IF($A12>=Premissas!$C$18,O12*(1-Premissas!$C$45)-Premissas!$C$46*MAX(0,O12*(1-Premissas!$C$45)-(SUM($W$5:$W$355)+Premissas!$C$26*Premissas!$C$60)),"") | AA12: =IF($A12>=Premissas!$C$18,Y12+Z12,"") | AB12: =AB11*(1+$P12)-X12 -> 298542.1 | AC12: =AND($A12>=Premissas!$C$16,$A12<EDATE(Premissas!$C$16,3))*Premissas!$C$10/3*(1+Premissas!$C$56)^$C12 -> 0 | AD12: =L12-M12-N12-AC12 -> 0 | AE12: =AE11+AD12 -> -288548.46 | AF12: =IF($A12>=Premissas!$C$18,O12*(1-Premissas!$C$45)-Premissas!$C$46*MAX(0,O12*(1-Premissas!$C$45)-(SUM($AC$5:$AC$355)+Premissas!$C$26*Premissas!$C$60)),"") | AG12: =IF($A12>=Premissas!$C$18,AE12+AF12,"") | AH12: =AH11*(1+$P12)-AD12 -> 303781.1 | AI12: =($A12=Premissas!$C$16)*0.2*Premissas!$C$11+AND($A12>Premissas!$C$16,$A12<=EDATE(Premissas!$C$16,43))*0.8*Premissas!$C$11/43*(1+Premissas!$C$56)^$C12 -> 5922.3508 | AJ12: =L12-M12-N12-AI12 -> -5922.3508 | AK12: =AK11+AJ12 -> -102614.48 | AL12: =IF($A12>=Premissas!$C$18,O12*(1-Premissas!$C$45)-Premissas!$C$46*MAX(0,O12*(1-Premissas!$C$45)-(SUM($AI$5:$AI$355)+Premissas!$C$26*Premissas!$C$60)),"") | AM12: =IF($A12>=Premissas!$C$18,AK12+AL12,"") | AN12: =AN11*(1+$P12)-AJ12 -> 107534.76 | AO12: =V12+S12 -> 15674.92
A13: =DATE(YEAR(A12),MONTH(A12)+1,1) -> 46539 | B13: =IF($A13<Premissas!$C$18,"Obra",IF($A13<Premissas!$C$20,"Entrega/mobília","Airbnb")) -> Obra | C13: =(YEAR($A13)-YEAR(Premissas!$C$16))*12+MONTH($A13)-MONTH(Premissas!$C$16) -> 8 | D13: =IF($A13>=Premissas!$C$20,Premissas!$C$31*IF(((YEAR($A13)-YEAR(Premissas!$C$20))*12+MONTH($A13)-MONTH(Premissas!$C$20))<Premissas!$C$33,Premissas!$C$34,1),0) -> 0 | E13: =D13*Premissas!$C$30*Premissas!$C$32*(1+Premissas!$C$58)^$C13 -> 0 | F13: =E13*Premissas!$C$35 -> 0 | G13: =E13*Premissas!$C$36 -> 0 | H13: =IF($A13>=Premissas!$C$18,Premissas!$C$37*(1+Premissas!$C$58)^$C13,0) -> 0 | I13: =IF($A13>=Premissas!$C$20,Premissas!$C$38*(1+Premissas!$C$58)^$C13,0) -> 0 | J13: =IF($A13>=Premissas!$C$20,Premissas!$C$39*(1+Premissas!$C$58)^$C13,0) -> 0 | K13: =IF($A13>=Premissas!$C$20,MAX(0,E13-F13-G13-H13)*Premissas!$C$41,0) -> 0 | L13: =E13-F13-G13-H13-I13-J13-K13 -> 0 | M13: =($A13=Premissas!$C$18)*Premissas!$C$26*Premissas!$C$60 -> 0 | N13: =IF(AND($A13>=Premissas!$C$18,$A13<Premissas!$C$20),Premissas!$C$27/MAX(1,Premissas!$C$19),0) -> 0 | O13: =IF($A13>=Premissas!$C$18,Premissas!$C$60*(1+Premissas!$C$59)^((YEAR($A13)-YEAR(Premissas!$C$18))*12+MONTH($A13)-MONTH(Premissas!$C$18)),"") | P13: =(1+IF(YEAR($A13)<=2026,Premissas!$C$49,IF(YEAR($A13)=2027,Premissas!$C$50,IF(YEAR($A13)=2028,Premissas!$C$51,Premissas!$C$52)))*(1-Premissas!$C$53))^(1/12)-1 -> 0.0084501625 | Q13: =($A13=Premissas!$C$16)*Premissas!$C$13 -> 0 | R13: =L13-M13-N13-Q13 -> 0 | S13: =S12+R13 -> -250000 | T13: =IF($A13>=Premissas!$C$18,O13*(1-Premissas!$C$45)-Premissas!$C$46*MAX(0,O13*(1-Premissas!$C$45)-(SUM($Q$5:$Q$355)+Premissas!$C$26*Premissas!$C$60)),"") | U13: =IF($A13>=Premissas!$C$18,S13+T13,"") | V13: =V12*(1+$P13)-R13 -> 267919.92 | W13: =($A13=Premissas!$C$16)*Premissas!$C$9 -> 0 | X13: =L13-M13-N13-W13 -> 0 | Y13: =Y12+X13 -> -280928 | Z13: =IF($A13>=Premissas!$C$18,O13*(1-Premissas!$C$45)-Premissas!$C$46*MAX(0,O13*(1-Premissas!$C$45)-(SUM($W$5:$W$355)+Premissas!$C$26*Premissas!$C$60)),"") | AA13: =IF($A13>=Premissas!$C$18,Y13+Z13,"") | AB13: =AB12*(1+$P13)-X13 -> 301064.82 | AC13: =AND($A13>=Premissas!$C$16,$A13<EDATE(Premissas!$C$16,3))*Premissas!$C$10/3*(1+Premissas!$C$56)^$C13 -> 0 | AD13: =L13-M13-N13-AC13 -> 0 | AE13: =AE12+AD13 -> -288548.46 | AF13: =IF($A13>=Premissas!$C$18,O13*(1-Premissas!$C$45)-Premissas!$C$46*MAX(0,O13*(1-Premissas!$C$45)-(SUM($AC$5:$AC$355)+Premissas!$C$26*Premissas!$C$60)),"") | AG13: =IF($A13>=Premissas!$C$18,AE13+AF13,"") | AH13: =AH12*(1+$P13)-AD13 -> 306348.1 | AI13: =($A13=Premissas!$C$16)*0.2*Premissas!$C$11+AND($A13>Premissas!$C$16,$A13<=EDATE(Premissas!$C$16,43))*0.8*Premissas!$C$11/43*(1+Premissas!$C$56)^$C13 -> 5948.8337 | AJ13: =L13-M13-N13-AI13 -> -5948.8337 | AK13: =AK12+AJ13 -> -108563.31 | AL13: =IF($A13>=Premissas!$C$18,O13*(1-Premissas!$C$45)-Premissas!$C$46*MAX(0,O13*(1-Premissas!$C$45)-(SUM($AI$5:$AI$355)+Premissas!$C$26*Premissas!$C$60)),"") | AM13: =IF($A13>=Premissas!$C$18,AK13+AL13,"") | AN13: =AN12*(1+$P13)-AJ13 -> 114392.28 | AO13: =V13+S13 -> 17919.916
A14: =DATE(YEAR(A13),MONTH(A13)+1,1) -> 46569 | B14: =IF($A14<Premissas!$C$18,"Obra",IF($A14<Premissas!$C$20,"Entrega/mobília","Airbnb")) -> Obra | C14: =(YEAR($A14)-YEAR(Premissas!$C$16))*12+MONTH($A14)-MONTH(Premissas!$C$16) -> 9 | D14: =IF($A14>=Premissas!$C$20,Premissas!$C$31*IF(((YEAR($A14)-YEAR(Premissas!$C$20))*12+MONTH($A14)-MONTH(Premissas!$C$20))<Premissas!$C$33,Premissas!$C$34,1),0) -> 0 | E14: =D14*Premissas!$C$30*Premissas!$C$32*(1+Premissas!$C$58)^$C14 -> 0 | F14: =E14*Premissas!$C$35 -> 0 | G14: =E14*Premissas!$C$36 -> 0 | H14: =IF($A14>=Premissas!$C$18,Premissas!$C$37*(1+Premissas!$C$58)^$C14,0) -> 0 | I14: =IF($A14>=Premissas!$C$20,Premissas!$C$38*(1+Premissas!$C$58)^$C14,0) -> 0 | J14: =IF($A14>=Premissas!$C$20,Premissas!$C$39*(1+Premissas!$C$58)^$C14,0) -> 0 | K14: =IF($A14>=Premissas!$C$20,MAX(0,E14-F14-G14-H14)*Premissas!$C$41,0) -> 0 | L14: =E14-F14-G14-H14-I14-J14-K14 -> 0 | M14: =($A14=Premissas!$C$18)*Premissas!$C$26*Premissas!$C$60 -> 0 | N14: =IF(AND($A14>=Premissas!$C$18,$A14<Premissas!$C$20),Premissas!$C$27/MAX(1,Premissas!$C$19),0) -> 0 | O14: =IF($A14>=Premissas!$C$18,Premissas!$C$60*(1+Premissas!$C$59)^((YEAR($A14)-YEAR(Premissas!$C$18))*12+MONTH($A14)-MONTH(Premissas!$C$18)),"") | P14: =(1+IF(YEAR($A14)<=2026,Premissas!$C$49,IF(YEAR($A14)=2027,Premissas!$C$50,IF(YEAR($A14)=2028,Premissas!$C$51,Premissas!$C$52)))*(1-Premissas!$C$53))^(1/12)-1 -> 0.0084501625 | Q14: =($A14=Premissas!$C$16)*Premissas!$C$13 -> 0 | R14: =L14-M14-N14-Q14 -> 0 | S14: =S13+R14 -> -250000 | T14: =IF($A14>=Premissas!$C$18,O14*(1-Premissas!$C$45)-Premissas!$C$46*MAX(0,O14*(1-Premissas!$C$45)-(SUM($Q$5:$Q$355)+Premissas!$C$26*Premissas!$C$60)),"") | U14: =IF($A14>=Premissas!$C$18,S14+T14,"") | V14: =V13*(1+$P14)-R14 -> 270183.88 | W14: =($A14=Premissas!$C$16)*Premissas!$C$9 -> 0 | X14: =L14-M14-N14-W14 -> 0 | Y14: =Y13+X14 -> -280928 | Z14: =IF($A14>=Premissas!$C$18,O14*(1-Premissas!$C$45)-Premissas!$C$46*MAX(0,O14*(1-Premissas!$C$45)-(SUM($W$5:$W$355)+Premissas!$C$26*Premissas!$C$60)),"") | AA14: =IF($A14>=Premissas!$C$18,Y14+Z14,"") | AB14: =AB13*(1+$P14)-X14 -> 303608.87 | AC14: =AND($A14>=Premissas!$C$16,$A14<EDATE(Premissas!$C$16,3))*Premissas!$C$10/3*(1+Premissas!$C$56)^$C14 -> 0 | AD14: =L14-M14-N14-AC14 -> 0 | AE14: =AE13+AD14 -> -288548.46 | AF14: =IF($A14>=Premissas!$C$18,O14*(1-Premissas!$C$45)-Premissas!$C$46*MAX(0,O14*(1-Premissas!$C$45)-(SUM($AC$5:$AC$355)+Premissas!$C$26*Premissas!$C$60)),"") | AG14: =IF($A14>=Premissas!$C$18,AE14+AF14,"") | AH14: =AH13*(1+$P14)-AD14 -> 308936.79 | AI14: =($A14=Premissas!$C$16)*0.2*Premissas!$C$11+AND($A14>Premissas!$C$16,$A14<=EDATE(Premissas!$C$16,43))*0.8*Premissas!$C$11/43*(1+Premissas!$C$56)^$C14 -> 5975.4351 | AJ14: =L14-M14-N14-AI14 -> -5975.4351 | AK14: =AK13+AJ14 -> -114538.75 | AL14: =IF($A14>=Premissas!$C$18,O14*(1-Premissas!$C$45)-Premissas!$C$46*MAX(0,O14*(1-Premissas!$C$45)-(SUM($AI$5:$AI$355)+Premissas!$C$26*Premissas!$C$60)),"") | AM14: =IF($A14>=Premissas!$C$18,AK14+AL14,"") | AN14: =AN13*(1+$P14)-AJ14 -> 121334.35 | AO14: =V14+S14 -> 20183.883
A15: =DATE(YEAR(A14),MONTH(A14)+1,1) -> 46600 | B15: =IF($A15<Premissas!$C$18,"Obra",IF($A15<Premissas!$C$20,"Entrega/mobília","Airbnb")) -> Obra | C15: =(YEAR($A15)-YEAR(Premissas!$C$16))*12+MONTH($A15)-MONTH(Premissas!$C$16) -> 10 | D15: =IF($A15>=Premissas!$C$20,Premissas!$C$31*IF(((YEAR($A15)-YEAR(Premissas!$C$20))*12+MONTH($A15)-MONTH(Premissas!$C$20))<Premissas!$C$33,Premissas!$C$34,1),0) -> 0 | E15: =D15*Premissas!$C$30*Premissas!$C$32*(1+Premissas!$C$58)^$C15 -> 0 | F15: =E15*Premissas!$C$35 -> 0 | G15: =E15*Premissas!$C$36 -> 0 | H15: =IF($A15>=Premissas!$C$18,Premissas!$C$37*(1+Premissas!$C$58)^$C15,0) -> 0 | I15: =IF($A15>=Premissas!$C$20,Premissas!$C$38*(1+Premissas!$C$58)^$C15,0) -> 0 | J15: =IF($A15>=Premissas!$C$20,Premissas!$C$39*(1+Premissas!$C$58)^$C15,0) -> 0 | K15: =IF($A15>=Premissas!$C$20,MAX(0,E15-F15-G15-H15)*Premissas!$C$41,0) -> 0 | L15: =E15-F15-G15-H15-I15-J15-K15 -> 0 | M15: =($A15=Premissas!$C$18)*Premissas!$C$26*Premissas!$C$60 -> 0 | N15: =IF(AND($A15>=Premissas!$C$18,$A15<Premissas!$C$20),Premissas!$C$27/MAX(1,Premissas!$C$19),0) -> 0 | O15: =IF($A15>=Premissas!$C$18,Premissas!$C$60*(1+Premissas!$C$59)^((YEAR($A15)-YEAR(Premissas!$C$18))*12+MONTH($A15)-MONTH(Premissas!$C$18)),"") | P15: =(1+IF(YEAR($A15)<=2026,Premissas!$C$49,IF(YEAR($A15)=2027,Premissas!$C$50,IF(YEAR($A15)=2028,Premissas!$C$51,Premissas!$C$52)))*(1-Premissas!$C$53))^(1/12)-1 -> 0.0084501625 | Q15: =($A15=Premissas!$C$16)*Premissas!$C$13 -> 0 | R15: =L15-M15-N15-Q15 -> 0 | S15: =S14+R15 -> -250000 | T15: =IF($A15>=Premissas!$C$18,O15*(1-Premissas!$C$45)-Premissas!$C$46*MAX(0,O15*(1-Premissas!$C$45)-(SUM($Q$5:$Q$355)+Premissas!$C$26*Premissas!$C$60)),"") | U15: =IF($A15>=Premissas!$C$18,S15+T15,"") | V15: =V14*(1+$P15)-R15 -> 272466.98 | W15: =($A15=Premissas!$C$16)*Premissas!$C$9 -> 0 | X15: =L15-M15-N15-W15 -> 0 | Y15: =Y14+X15 -> -280928 | Z15: =IF($A15>=Premissas!$C$18,O15*(1-Premissas!$C$45)-Premissas!$C$46*MAX(0,O15*(1-Premissas!$C$45)-(SUM($W$5:$W$355)+Premissas!$C$26*Premissas!$C$60)),"") | AA15: =IF($A15>=Premissas!$C$18,Y15+Z15,"") | AB15: =AB14*(1+$P15)-X15 -> 306174.42 | AC15: =AND($A15>=Premissas!$C$16,$A15<EDATE(Premissas!$C$16,3))*Premissas!$C$10/3*(1+Premissas!$C$56)^$C15 -> 0 | AD15: =L15-M15-N15-AC15 -> 0 | AE15: =AE14+AD15 -> -288548.46 | AF15: =IF($A15>=Premissas!$C$18,O15*(1-Premissas!$C$45)-Premissas!$C$46*MAX(0,O15*(1-Premissas!$C$45)-(SUM($AC$5:$AC$355)+Premissas!$C$26*Premissas!$C$60)),"") | AG15: =IF($A15>=Premissas!$C$18,AE15+AF15,"") | AH15: =AH14*(1+$P15)-AD15 -> 311547.35 | AI15: =($A15=Premissas!$C$16)*0.2*Premissas!$C$11+AND($A15>Premissas!$C$16,$A15<=EDATE(Premissas!$C$16,43))*0.8*Premissas!$C$11/43*(1+Premissas!$C$56)^$C15 -> 6002.1555 | AJ15: =L15-M15-N15-AI15 -> -6002.1555 | AK15: =AK14+AJ15 -> -120540.9 | AL15: =IF($A15>=Premissas!$C$18,O15*(1-Premissas!$C$45)-Premissas!$C$46*MAX(0,O15*(1-Premissas!$C$45)-(SUM($AI$5:$AI$355)+Premissas!$C$26*Premissas!$C$60)),"") | AM15: =IF($A15>=Premissas!$C$18,AK15+AL15,"") | AN15: =AN14*(1+$P15)-AJ15 -> 128361.8 | AO15: =V15+S15 -> 22466.981
A16: =DATE(YEAR(A15),MONTH(A15)+1,1) -> 46631 | B16: =IF($A16<Premissas!$C$18,"Obra",IF($A16<Premissas!$C$20,"Entrega/mobília","Airbnb")) -> Obra | C16: =(YEAR($A16)-YEAR(Premissas!$C$16))*12+MONTH($A16)-MONTH(Premissas!$C$16) -> 11 | D16: =IF($A16>=Premissas!$C$20,Premissas!$C$31*IF(((YEAR($A16)-YEAR(Premissas!$C$20))*12+MONTH($A16)-MONTH(Premissas!$C$20))<Premissas!$C$33,Premissas!$C$34,1),0) -> 0 | E16: =D16*Premissas!$C$30*Premissas!$C$32*(1+Premissas!$C$58)^$C16 -> 0 | F16: =E16*Premissas!$C$35 -> 0 | G16: =E16*Premissas!$C$36 -> 0 | H16: =IF($A16>=Premissas!$C$18,Premissas!$C$37*(1+Premissas!$C$58)^$C16,0) -> 0 | I16: =IF($A16>=Premissas!$C$20,Premissas!$C$38*(1+Premissas!$C$58)^$C16,0) -> 0 | J16: =IF($A16>=Premissas!$C$20,Premissas!$C$39*(1+Premissas!$C$58)^$C16,0) -> 0 | K16: =IF($A16>=Premissas!$C$20,MAX(0,E16-F16-G16-H16)*Premissas!$C$41,0) -> 0 | L16: =E16-F16-G16-H16-I16-J16-K16 -> 0 | M16: =($A16=Premissas!$C$18)*Premissas!$C$26*Premissas!$C$60 -> 0 | N16: =IF(AND($A16>=Premissas!$C$18,$A16<Premissas!$C$20),Premissas!$C$27/MAX(1,Premissas!$C$19),0) -> 0 | O16: =IF($A16>=Premissas!$C$18,Premissas!$C$60*(1+Premissas!$C$59)^((YEAR($A16)-YEAR(Premissas!$C$18))*12+MONTH($A16)-MONTH(Premissas!$C$18)),"") | P16: =(1+IF(YEAR($A16)<=2026,Premissas!$C$49,IF(YEAR($A16)=2027,Premissas!$C$50,IF(YEAR($A16)=2028,Premissas!$C$51,Premissas!$C$52)))*(1-Premissas!$C$53))^(1/12)-1 -> 0.0084501625 | Q16: =($A16=Premissas!$C$16)*Premissas!$C$13 -> 0 | R16: =L16-M16-N16-Q16 -> 0 | S16: =S15+R16 -> -250000 | T16: =IF($A16>=Premissas!$C$18,O16*(1-Premissas!$C$45)-Premissas!$C$46*MAX(0,O16*(1-Premissas!$C$45)-(SUM($Q$5:$Q$355)+Premissas!$C$26*Premissas!$C$60)),"") | U16: =IF($A16>=Premissas!$C$18,S16+T16,"") | V16: =V15*(1+$P16)-R16 -> 274769.37 | W16: =($A16=Premissas!$C$16)*Premissas!$C$9 -> 0 | X16: =L16-M16-N16-W16 -> 0 | Y16: =Y15+X16 -> -280928 | Z16: =IF($A16>=Premissas!$C$18,O16*(1-Premissas!$C$45)-Premissas!$C$46*MAX(0,O16*(1-Premissas!$C$45)-(SUM($W$5:$W$355)+Premissas!$C$26*Premissas!$C$60)),"") | AA16: =IF($A16>=Premissas!$C$18,Y16+Z16,"") | AB16: =AB15*(1+$P16)-X16 -> 308761.64 | AC16: =AND($A16>=Premissas!$C$16,$A16<EDATE(Premissas!$C$16,3))*Premissas!$C$10/3*(1+Premissas!$C$56)^$C16 -> 0 | AD16: =L16-M16-N16-AC16 -> 0 | AE16: =AE15+AD16 -> -288548.46 | AF16: =IF($A16>=Premissas!$C$18,O16*(1-Premissas!$C$45)-Premissas!$C$46*MAX(0,O16*(1-Premissas!$C$45)-(SUM($AC$5:$AC$355)+Premissas!$C$26*Premissas!$C$60)),"") | AG16: =IF($A16>=Premissas!$C$18,AE16+AF16,"") | AH16: =AH15*(1+$P16)-AD16 -> 314179.98 | AI16: =($A16=Premissas!$C$16)*0.2*Premissas!$C$11+AND($A16>Premissas!$C$16,$A16<=EDATE(Premissas!$C$16,43))*0.8*Premissas!$C$11/43*(1+Premissas!$C$56)^$C16 -> 6028.9953 | AJ16: =L16-M16-N16-AI16 -> -6028.9953 | AK16: =AK15+AJ16 -> -126569.9 | AL16: =IF($A16>=Premissas!$C$18,O16*(1-Premissas!$C$45)-Premissas!$C$46*MAX(0,O16*(1-Premissas!$C$45)-(SUM($AI$5:$AI$355)+Premissas!$C$26*Premissas!$C$60)),"") | AM16: =IF($A16>=Premissas!$C$18,AK16+AL16,"") | AN16: =AN15*(1+$P16)-AJ16 -> 135475.47 | AO16: =V16+S16 -> 24769.371
A17: =DATE(YEAR(A16),MONTH(A16)+1,1) -> 46661 | B17: =IF($A17<Premissas!$C$18,"Obra",IF($A17<Premissas!$C$20,"Entrega/mobília","Airbnb")) -> Obra | C17: =(YEAR($A17)-YEAR(Premissas!$C$16))*12+MONTH($A17)-MONTH(Premissas!$C$16) -> 12 | D17: =IF($A17>=Premissas!$C$20,Premissas!$C$31*IF(((YEAR($A17)-YEAR(Premissas!$C$20))*12+MONTH($A17)-MONTH(Premissas!$C$20))<Premissas!$C$33,Premissas!$C$34,1),0) -> 0 | E17: =D17*Premissas!$C$30*Premissas!$C$32*(1+Premissas!$C$58)^$C17 -> 0 | F17: =E17*Premissas!$C$35 -> 0 | G17: =E17*Premissas!$C$36 -> 0 | H17: =IF($A17>=Premissas!$C$18,Premissas!$C$37*(1+Premissas!$C$58)^$C17,0) -> 0 | I17: =IF($A17>=Premissas!$C$20,Premissas!$C$38*(1+Premissas!$C$58)^$C17,0) -> 0 | J17: =IF($A17>=Premissas!$C$20,Premissas!$C$39*(1+Premissas!$C$58)^$C17,0) -> 0 | K17: =IF($A17>=Premissas!$C$20,MAX(0,E17-F17-G17-H17)*Premissas!$C$41,0) -> 0 | L17: =E17-F17-G17-H17-I17-J17-K17 -> 0 | M17: =($A17=Premissas!$C$18)*Premissas!$C$26*Premissas!$C$60 -> 0 | N17: =IF(AND($A17>=Premissas!$C$18,$A17<Premissas!$C$20),Premissas!$C$27/MAX(1,Premissas!$C$19),0) -> 0 | O17: =IF($A17>=Premissas!$C$18,Premissas!$C$60*(1+Premissas!$C$59)^((YEAR($A17)-YEAR(Premissas!$C$18))*12+MONTH($A17)-MONTH(Premissas!$C$18)),"") | P17: =(1+IF(YEAR($A17)<=2026,Premissas!$C$49,IF(YEAR($A17)=2027,Premissas!$C$50,IF(YEAR($A17)=2028,Premissas!$C$51,Premissas!$C$52)))*(1-Premissas!$C$53))^(1/12)-1 -> 0.0084501625 | Q17: =($A17=Premissas!$C$16)*Premissas!$C$13 -> 0 | R17: =L17-M17-N17-Q17 -> 0 | S17: =S16+R17 -> -250000 | T17: =IF($A17>=Premissas!$C$18,O17*(1-Premissas!$C$45)-Premissas!$C$46*MAX(0,O17*(1-Premissas!$C$45)-(SUM($Q$5:$Q$355)+Premissas!$C$26*Premissas!$C$60)),"") | U17: =IF($A17>=Premissas!$C$18,S17+T17,"") | V17: =V16*(1+$P17)-R17 -> 277091.22 | W17: =($A17=Premissas!$C$16)*Premissas!$C$9 -> 0 | X17: =L17-M17-N17-W17 -> 0 | Y17: =Y16+X17 -> -280928 | Z17: =IF($A17>=Premissas!$C$18,O17*(1-Premissas!$C$45)-Premissas!$C$46*MAX(0,O17*(1-Premissas!$C$45)-(SUM($W$5:$W$355)+Premissas!$C$26*Premissas!$C$60)),"") | AA17: =IF($A17>=Premissas!$C$18,Y17+Z17,"") | AB17: =AB16*(1+$P17)-X17 -> 311370.73 | AC17: =AND($A17>=Premissas!$C$16,$A17<EDATE(Premissas!$C$16,3))*Premissas!$C$10/3*(1+Premissas!$C$56)^$C17 -> 0 | AD17: =L17-M17-N17-AC17 -> 0 | AE17: =AE16+AD17 -> -288548.46 | AF17: =IF($A17>=Premissas!$C$18,O17*(1-Premissas!$C$45)-Premissas!$C$46*MAX(0,O17*(1-Premissas!$C$45)-(SUM($AC$5:$AC$355)+Premissas!$C$26*Premissas!$C$60)),"") | AG17: =IF($A17>=Premissas!$C$18,AE17+AF17,"") | AH17: =AH16*(1+$P17)-AD17 -> 316834.85 | AI17: =($A17=Premissas!$C$16)*0.2*Premissas!$C$11+AND($A17>Premissas!$C$16,$A17<=EDATE(Premissas!$C$16,43))*0.8*Premissas!$C$11/43*(1+Premissas!$C$56)^$C17 -> 6055.9552 | AJ17: =L17-M17-N17-AI17 -> -6055.9552 | AK17: =AK16+AJ17 -> -132625.85 | AL17: =IF($A17>=Premissas!$C$18,O17*(1-Premissas!$C$45)-Premissas!$C$46*MAX(0,O17*(1-Premissas!$C$45)-(SUM($AI$5:$AI$355)+Premissas!$C$26*Premissas!$C$60)),"") | AM17: =IF($A17>=Premissas!$C$18,AK17+AL17,"") | AN17: =AN16*(1+$P17)-AJ17 -> 142676.21 | AO17: =V17+S17 -> 27091.217
